Workbook

Sheet Overview
B1: 🎓 9-Month Study Plan · SDE & Full-Stack Web Developer
B2: Built from the Scaler Academy brochure and the Besant Technologies syllabus · edit the yellow cells to personalise · Developed by Rajesh Kumar Singh
B3: ⚙️ YOUR INPUTS
B4: Plan start date (use a Monday) | C4: 46307 | D4: =IF(WEEKDAY(C4,2)=1,"✔ Monday","⚠ Not a Monday") -> ✔ Monday
B5: Study hours per week | C5: 20 | D5: Compressed plan: aim for 18–22 h/week
B6: Experience level (SDE plan) | C6: Intermediate | D6: Intermediate = 39 wks · Beginner adds 8 wks (≈11 months) · Advanced skips Intermediate DSA
B8: 🧠 SDE Plan
B9: SDE Plan | C9: WEEKS PLANNED | E9: TOTAL HOURS | G9: PLANNED FINISH | I9: PROGRESS
C10: =COUNTIF('SDE Plan'!$B$6:$B$78,"Yes") -> 39 | E10: =COUNTIF('SDE Plan'!$B$6:$B$78,"Yes")*$C$5 -> 780 | G10: =IF(COUNTIF('SDE Plan'!$B$6:$B$78,"Yes")=0,"—",MAX('SDE Plan'!$D$6:$D$78)) -> 46579 | I10: =IF(COUNTIF('SDE Plan'!$B$6:$B$78,"Yes")=0,0,COUNTIFS('SDE Plan'!$B$6:$B$78,"Yes",'SDE Plan'!$L$6:$L$78,"Done")/COUNTIF('SDE Plan'!$B$6:$B$78,"Yes")) -> 0
C12: =ROUND(COUNTIF('SDE Plan'!$B$6:$B$78,"Yes")/4.345,1)&" months"&IF(COUNTIF('SDE Plan'!$B$6:$B$78,"Yes")<=39," ✔ fits 9 mo"," ⚠ over 9 mo") -> 9 months ✔ fits 9 mo | E12: ="at "&$C$5&" h / week" -> at 20 h / week | G12: ="starts "&TEXT($C$4,"dd mmm yyyy") -> starts 12 Oct 2026 | I12: =COUNTIFS('SDE Plan'!$B$6:$B$78,"Yes",'SDE Plan'!$L$6:$L$78,"Done")&" of "&COUNTIF('SDE Plan'!$B$6:$B$78,"Yes")&" weeks done" -> 0 of 39 weeks done
B14: 🌐 Full-Stack Plan
B15: Full-Stack Plan | C15: WEEKS PLANNED | E15: TOTAL HOURS | G15: PLANNED FINISH | I15: PROGRESS
C16: =COUNTIF('FullStack Plan'!$B$6:$B$78,"Yes") -> 39 | E16: =COUNTIF('FullStack Plan'!$B$6:$B$78,"Yes")*$C$5 -> 780 | G16: =IF(COUNTIF('FullStack Plan'!$B$6:$B$78,"Yes")=0,"—",MAX('FullStack Plan'!$D$6:$D$78)) -> 46579 | I16: =IF(COUNTIF('FullStack Plan'!$B$6:$B$78,"Yes")=0,0,COUNTIFS('FullStack Plan'!$B$6:$B$78,"Yes",'FullStack Plan'!$L$6:$L$78,"Done")/COUNTIF('FullStack Plan'!$B$6:$B$78,"Yes")) -> 0
C18: =ROUND(COUNTIF('FullStack Plan'!$B$6:$B$78,"Yes")/4.345,1)&" months"&IF(COUNTIF('FullStack Plan'!$B$6:$B$78,"Yes")<=39," ✔ fits 9 mo"," ⚠ over 9 mo") -> 9 months ✔ fits 9 mo | E18: ="at "&$C$5&" h / week" -> at 20 h / week | G18: ="starts "&TEXT($C$4,"dd mmm yyyy") -> starts 12 Oct 2026 | I18: =COUNTIFS('FullStack Plan'!$B$6:$B$78,"Yes",'FullStack Plan'!$L$6:$L$78,"Done")&" of "&COUNTIF('FullStack Plan'!$B$6:$B$78,"Yes")&" weeks done" -> 0 of 39 weeks done
B20: 📊 WEEKS BY PHASE
B21: Phase | C21: SDE | D21: Full-Stack
B22: 0. 🧱 Foundations | C22: =SUMIFS('Module Summary'!$D$5:$D$43,'Module Summary'!$B$5:$B$43,$B22,'Module Summary'!$A$5:$A$43,"SDE") -> 0 | D22: =SUMIFS('Module Summary'!$D$5:$D$43,'Module Summary'!$B$5:$B$43,$B22,'Module Summary'!$A$5:$A$43,"Full-Stack") -> 0
B23: 1. 🌐 Web Foundations | C23: =SUMIFS('Module Summary'!$D$5:$D$43,'Module Summary'!$B$5:$B$43,$B23,'Module Summary'!$A$5:$A$43,"SDE") -> 0 | D23: =SUMIFS('Module Summary'!$D$5:$D$43,'Module Summary'!$B$5:$B$43,$B23,'Module Summary'!$A$5:$A$43,"Full-Stack") -> 2
B24: 1. 🧩 Problem Solving | C24: =SUMIFS('Module Summary'!$D$5:$D$43,'Module Summary'!$B$5:$B$43,$B24,'Module Summary'!$A$5:$A$43,"SDE") -> 2 | D24: =SUMIFS('Module Summary'!$D$5:$D$43,'Module Summary'!$B$5:$B$43,$B24,'Module Summary'!$A$5:$A$43,"Full-Stack") -> 0
B25: 2. ⚡ JavaScript | C25: =SUMIFS('Module Summary'!$D$5:$D$43,'Module Summary'!$B$5:$B$43,$B25,'Module Summary'!$A$5:$A$43,"SDE") -> 0 | D25: =SUMIFS('Module Summary'!$D$5:$D$43,'Module Summary'!$B$5:$B$43,$B25,'Module Summary'!$A$5:$A$43,"Full-Stack") -> 8
B26: 2. 🤖 AI Skills | C26: =SUMIFS('Module Summary'!$D$5:$D$43,'Module Summary'!$B$5:$B$43,$B26,'Module Summary'!$A$5:$A$43,"SDE") -> 2 | D26: =SUMIFS('Module Summary'!$D$5:$D$43,'Module Summary'!$B$5:$B$43,$B26,'Module Summary'!$A$5:$A$43,"Full-Stack") -> 0
B27: 3. ⚛️ React | C27: =SUMIFS('Module Summary'!$D$5:$D$43,'Module Summary'!$B$5:$B$43,$B27,'Module Summary'!$A$5:$A$43,"SDE") -> 0 | D27: =SUMIFS('Module Summary'!$D$5:$D$43,'Module Summary'!$B$5:$B$43,$B27,'Module Summary'!$A$5:$A$43,"Full-Stack") -> 4
B28: 3. 🧠 DSA | C28: =SUMIFS('Module Summary'!$D$5:$D$43,'Module Summary'!$B$5:$B$43,$B28,'Module Summary'!$A$5:$A$43,"SDE") -> 13 | D28: =SUMIFS('Module Summary'!$D$5:$D$43,'Module Summary'!$B$5:$B$43,$B28,'Module Summary'!$A$5:$A$43,"Full-Stack") -> 0
B29: 4. 🗄️ Databases | C29: =SUMIFS('Module Summary'!$D$5:$D$43,'Module Summary'!$B$5:$B$43,$B29,'Module Summary'!$A$5:$A$43,"SDE") -> 2 | D29: =SUMIFS('Module Summary'!$D$5:$D$43,'Module Summary'!$B$5:$B$43,$B29,'Module Summary'!$A$5:$A$43,"Full-Stack") -> 0
B30: 4. 🛠️ Backend (MERN) | C30: =SUMIFS('Module Summary'!$D$5:$D$43,'Module Summary'!$B$5:$B$43,$B30,'Module Summary'!$A$5:$A$43,"SDE") -> 0 | D30: =SUMIFS('Module Summary'!$D$5:$D$43,'Module Summary'!$B$5:$B$43,$B30,'Module Summary'!$A$5:$A$43,"Full-Stack") -> 10
B31: 5. ⚙️ Backend & LLD | C31: =SUMIFS('Module Summary'!$D$5:$D$43,'Module Summary'!$B$5:$B$43,$B31,'Module Summary'!$A$5:$A$43,"SDE") -> 14 | D31: =SUMIFS('Module Summary'!$D$5:$D$43,'Module Summary'!$B$5:$B$43,$B31,'Module Summary'!$A$5:$A$43,"Full-Stack") -> 0
B32: 5. 🚀 Advanced Frontend | C32: =SUMIFS('Module Summary'!$D$5:$D$43,'Module Summary'!$B$5:$B$43,$B32,'Module Summary'!$A$5:$A$43,"SDE") -> 0 | D32: =SUMIFS('Module Summary'!$D$5:$D$43,'Module Summary'!$B$5:$B$43,$B32,'Module Summary'!$A$5:$A$43,"Full-Stack") -> 6
B33: 6. 🏆 Capstone | C33: =SUMIFS('Module Summary'!$D$5:$D$43,'Module Summary'!$B$5:$B$43,$B33,'Module Summary'!$A$5:$A$43,"SDE") -> 0 | D33: =SUMIFS('Module Summary'!$D$5:$D$43,'Module Summary'!$B$5:$B$43,$B33,'Module Summary'!$A$5:$A$43,"Full-Stack") -> 3
... B38: 8. ✨ Optional extensions | C38: =SUMIFS('Module Summary'!$D$5:$D$43,'Module Summary'!$B$5:$B$43,$B38,'Module Summary'!$A$5:$A$43,"SDE") -> 0 | D38: =SUMIFS('Module Summary'!$D$5:$D$43,'Module Summary'!$B$5:$B$43,$B38,'Module Summary'!$A$5:$A$43,"Full-Stack") -> 0
B39: Total weeks | C39: =SUM(C22:C38) -> 39 | D39: =SUM(D22:D38) -> 39
B41: 🧭 HOW TO USE
B42: 1. Set the start date, weekly hours and level in the yellow cells above.
B43: 2. Open SDE Plan / FullStack Plan – each row is one week: topics, 📖 reading link, ▶ YouTube link, practice & milestone.
B44: 3. Set Include? to No to skip a week or module – dates, Timeline and totals re-flow automatically (grey rows are skipped).
B45: 4. Update Status each week: the cards above, Timeline (dark-green = done) and Module Summary update live.
B46: 5. Month Plan = your 9-month view · Timeline = Gantt chart · Resources = more links · Projects = portfolio tracker.
B47: Legend: blue text = you edit · black = formula · yellow fill = key input · grey rows = skipped. Include? for the first SDE modules follows your level – overwrite with Yes/No to override.
B49: 🎯 WHICH PLAN SHOULD I FOLLOW?
B50: 🧠 SDE Plan → product-company / FAANG-style interviews: DSA, LLD, HLD, Java/Spring backend, AI skills.
B51: 🌐 Full-Stack Plan → web-product roles: HTML/CSS, JavaScript, React, Node/Express/MongoDB, SQL + light DSA.
...

Sheet Month Plan
A1: 9-Month Roadmap – month by month
A2: Auto-built from the plan sheets (Include? changes flow through). Plan weeks are numbered 1–39; if you pick Beginner or switch on extras, later weeks run past month 9.
A4: Month | B4: Plan weeks | C4: From (wk 1 of month) | D4: SDE focus | E4: Full-Stack focus | F4: Hours (SDE / FS) | G4: Month goal | H4: wk from | I4: wk to
A5: Month 1 | B5: 1–4 | C5: =IFERROR(INDEX('SDE Plan'!$C$6:$C$78,MATCH($H5,'SDE Plan'!$A$6:$A$78,0)),"—") -> 46307 | D5: =IFERROR(IF(INDEX('SDE Plan'!$F$6:$F$78,MATCH($H5,'SDE Plan'!$A$6:$A$78,0))=INDEX('SDE Plan'!$F$6:$F$78,MATCH($I5,'SDE Plan'!$A$6:$A$78,0)),INDEX('SDE Plan'!$F$6:$F$78,MATCH($H5,'SDE Plan'!$A$6:$A$78,0)),INDEX('SDE Plan'!$F$6:$F$78,MATCH($H5,'SDE Plan'!$A$6:$A$78,0))&" → "&INDEX('SDE Plan'!$F$6:$F$78,MATCH($I5,'SDE Plan'!$A$6:$A$78,0))),"—") -> Intermediate DSA: AI-Assisted Problem Solving → Agentic AI: From Talking to AI to Building One | E5: =IFERROR(IF(INDEX('FullStack Plan'!$F$6:$F$78,MATCH($H5,'FullStack Plan'!$A$6:$A$78,0))=INDEX('FullStack Plan'!$F$6:$F$78,MATCH($I5,'FullStack Plan'!$A$6:$A$78,0)),INDEX('FullStack Plan'!$F$6:$F$78,MATCH($H5,'FullStack Plan'!$A$6:$A$78,0)),INDEX('FullStack Plan'!$F$6:$F$78,MATCH($H5,'FullStack Plan'!$A$6:$A$78,0))&" → "&INDEX('FullStack Plan'!$F$6:$F$78,MATCH($I5,'FullStack Plan'!$A$6:$A$78,0))),"—") -> HTML & CSS Foundations → JavaScript Runtime Systems, Browser APIs & Product Labs | F5: =(I5-H5+1)*Overview!$C$5 -> 80 | G5: Checkpoint: first module contest passed + one mini project on GitHub | H5: 1 | I5: 4
A6: Month 2 | B6: 5–9 | C6: =IFERROR(INDEX('SDE Plan'!$C$6:$C$78,MATCH($H6,'SDE Plan'!$A$6:$A$78,0)),"—") -> 46335 | D6: =IFERROR(IF(INDEX('SDE Plan'!$F$6:$F$78,MATCH($H6,'SDE Plan'!$A$6:$A$78,0))=INDEX('SDE Plan'!$F$6:$F$78,MATCH($I6,'SDE Plan'!$A$6:$A$78,0)),INDEX('SDE Plan'!$F$6:$F$78,MATCH($H6,'SDE Plan'!$A$6:$A$78,0)),INDEX('SDE Plan'!$F$6:$F$78,MATCH($H6,'SDE Plan'!$A$6:$A$78,0))&" → "&INDEX('SDE Plan'!$F$6:$F$78,MATCH($I6,'SDE Plan'!$A$6:$A$78,0))),"—") -> Advanced DSA: Foundations – Core Techniques & Optimization → Advanced DSA: Linear & Non-Linear Structures | E6: =IFERROR(IF(INDEX('FullStack Plan'!$F$6:$F$78,MATCH($H6,'FullStack Plan'!$A$6:$A$78,0))=INDEX('FullStack Plan'!$F$6:$F$78,MATCH($I6,'FullStack Plan'!$A$6:$A$78,0)),INDEX('FullStack Plan'!$F$6:$F$78,MATCH($H6,'FullStack Plan'!$A$6:$A$78,0)),INDEX('FullStack Plan'!$F$6:$F$78,MATCH($H6,'FullStack Plan'!$A$6:$A$78,0))&" → "&INDEX('FullStack Plan'!$F$6:$F$78,MATCH($I6,'FullStack Plan'!$A$6:$A$78,0))),"—") -> JavaScript Runtime Systems, Browser APIs & Product Labs → JavaScript Object System & Engineering Patterns | F6: =(I6-H6+1)*Overview!$C$5 -> 100 | G6: Checkpoint: 40+ DSA problems solved; first deployed page/app | H6: 5 | I6: 9
A7: Month 3 | B7: 10–13 | C7: =IFERROR(INDEX('SDE Plan'!$C$6:$C$78,MATCH($H7,'SDE Plan'!$A$6:$A$78,0)),"—") -> 46370 | D7: =IFERROR(IF(INDEX('SDE Plan'!$F$6:$F$78,MATCH($H7,'SDE Plan'!$A$6:$A$78,0))=INDEX('SDE Plan'!$F$6:$F$78,MATCH($I7,'SDE Plan'!$A$6:$A$78,0)),INDEX('SDE Plan'!$F$6:$F$78,MATCH($H7,'SDE Plan'!$A$6:$A$78,0)),INDEX('SDE Plan'!$F$6:$F$78,MATCH($H7,'SDE Plan'!$A$6:$A$78,0))&" → "&INDEX('SDE Plan'!$F$6:$F$78,MATCH($I7,'SDE Plan'!$A$6:$A$78,0))),"—") -> Advanced DSA: Linear & Non-Linear Structures → Advanced DSA: Backtracking & Advanced Trees | E7: =IFERROR(IF(INDEX('FullStack Plan'!$F$6:$F$78,MATCH($H7,'FullStack Plan'!$A$6:$A$78,0))=INDEX('FullStack Plan'!$F$6:$F$78,MATCH($I7,'FullStack Plan'!$A$6:$A$78,0)),INDEX('FullStack Plan'!$F$6:$F$78,MATCH($H7,'FullStack Plan'!$A$6:$A$78,0)),INDEX('FullStack Plan'!$F$6:$F$78,MATCH($H7,'FullStack Plan'!$A$6:$A$78,0))&" → "&INDEX('FullStack Plan'!$F$6:$F$78,MATCH($I7,'FullStack Plan'!$A$6:$A$78,0))),"—") -> JavaScript Object System & Engineering Patterns → React & Frontend Product Architecture Fundamentals | F7: =(I7-H7+1)*Overview!$C$5 -> 80 | G7: Checkpoint: 80+ DSA problems; second project live | H7: 10 | I7: 13
A8: Month 4 | B8: 14–17 | C8: =IFERROR(INDEX('SDE Plan'!$C$6:$C$78,MATCH($H8,'SDE Plan'!$A$6:$A$78,0)),"—") -> 46398 | D8: =IFERROR(IF(INDEX('SDE Plan'!$F$6:$F$78,MATCH($H8,'SDE Plan'!$A$6:$A$78,0))=INDEX('SDE Plan'!$F$6:$F$78,MATCH($I8,'SDE Plan'!$A$6:$A$78,0)),INDEX('SDE Plan'!$F$6:$F$78,MATCH($H8,'SDE Plan'!$A$6:$A$78,0)),INDEX('SDE Plan'!$F$6:$F$78,MATCH($H8,'SDE Plan'!$A$6:$A$78,0))&" → "&INDEX('SDE Plan'!$F$6:$F$78,MATCH($I8,'SDE Plan'!$A$6:$A$78,0))),"—") -> Advanced DSA: DP, Heaps & Graphs – Crack It with AI Edge | E8: =IFERROR(IF(INDEX('FullStack Plan'!$F$6:$F$78,MATCH($H8,'FullStack Plan'!$A$6:$A$78,0))=INDEX('FullStack Plan'!$F$6:$F$78,MATCH($I8,'FullStack Plan'!$A$6:$A$78,0)),INDEX('FullStack Plan'!$F$6:$F$78,MATCH($H8,'FullStack Plan'!$A$6:$A$78,0)),INDEX('FullStack Plan'!$F$6:$F$78,MATCH($H8,'FullStack Plan'!$A$6:$A$78,0))&" → "&INDEX('FullStack Plan'!$F$6:$F$78,MATCH($I8,'FullStack Plan'!$A$6:$A$78,0))),"—") -> React & Frontend Product Architecture Fundamentals → Backend Product Systems, APIs & Production Engineering (MERN) | F8: =(I8-H8+1)*Overview!$C$5 -> 80 | G8: Checkpoint: DSA phase done / React app live; 1 mock interview | H8: 14 | I8: 17
A9: Month 5 | B9: 18–22 | C9: =IFERROR(INDEX('SDE Plan'!$C$6:$C$78,MATCH($H9,'SDE Plan'!$A$6:$A$78,0)),"—") -> 46426 | D9: =IFERROR(IF(INDEX('SDE Plan'!$F$6:$F$78,MATCH($H9,'SDE Plan'!$A$6:$A$78,0))=INDEX('SDE Plan'!$F$6:$F$78,MATCH($I9,'SDE Plan'!$A$6:$A$78,0)),INDEX('SDE Plan'!$F$6:$F$78,MATCH($H9,'SDE Plan'!$A$6:$A$78,0)),INDEX('SDE Plan'!$F$6:$F$78,MATCH($H9,'SDE Plan'!$A$6:$A$78,0))&" → "&INDEX('SDE Plan'!$F$6:$F$78,MATCH($I9,'SDE Plan'!$A$6:$A$78,0))),"—") -> Databases & SQL → Foundations of Object-Oriented Design & Scalable Systems | E9: =IFERROR(IF(INDEX('FullStack Plan'!$F$6:$F$78,MATCH($H9,'FullStack Plan'!$A$6:$A$78,0))=INDEX('FullStack Plan'!$F$6:$F$78,MATCH($I9,'FullStack Plan'!$A$6:$A$78,0)),INDEX('FullStack Plan'!$F$6:$F$78,MATCH($H9,'FullStack Plan'!$A$6:$A$78,0)),INDEX('FullStack Plan'!$F$6:$F$78,MATCH($H9,'FullStack Plan'!$A$6:$A$78,0))&" → "&INDEX('FullStack Plan'!$F$6:$F$78,MATCH($I9,'FullStack Plan'!$A$6:$A$78,0))),"—") -> Backend Product Systems, APIs & Production Engineering (MERN) → Databases & SQL | F9: =(I9-H9+1)*Overview!$C$5 -> 100 | G9: Checkpoint: SQL contest passed; backend API running with a database | H9: 18 | I9: 22
A10: Month 6 | B10: 23–26 | C10: =IFERROR(INDEX('SDE Plan'!$C$6:$C$78,MATCH($H10,'SDE Plan'!$A$6:$A$78,0)),"—") -> 46461 | D10: =IFERROR(IF(INDEX('SDE Plan'!$F$6:$F$78,MATCH($H10,'SDE Plan'!$A$6:$A$78,0))=INDEX('SDE Plan'!$F$6:$F$78,MATCH($I10,'SDE Plan'!$A$6:$A$78,0)),INDEX('SDE Plan'!$F$6:$F$78,MATCH($H10,'SDE Plan'!$A$6:$A$78,0)),INDEX('SDE Plan'!$F$6:$F$78,MATCH($H10,'SDE Plan'!$A$6:$A$78,0))&" → "&INDEX('SDE Plan'!$F$6:$F$78,MATCH($I10,'SDE Plan'!$A$6:$A$78,0))),"—") -> Design Principles & Patterns for Extensible Systems → Applied Design & Machine Coding | E10: =IFERROR(IF(INDEX('FullStack Plan'!$F$6:$F$78,MATCH($H10,'FullStack Plan'!$A$6:$A$78,0))=INDEX('FullStack Plan'!$F$6:$F$78,MATCH($I10,'FullStack Plan'!$A$6:$A$78,0)),INDEX('FullStack Plan'!$F$6:$F$78,MATCH($H10,'FullStack Plan'!$A$6:$A$78,0)),INDEX('FullStack Plan'!$F$6:$F$78,MATCH($H10,'FullStack Plan'!$A$6:$A$78,0))&" → "&INDEX('FullStack Plan'!$F$6:$F$78,MATCH($I10,'FullStack Plan'!$A$6:$A$78,0))),"—") -> Backend Product Systems – Deep Dive → React, TypeScript & Frontend Architecture – Deep Dive (incl. Next.js) | F10: =(I10-H10+1)*Overview!$C$5 -> 80 | G10: Checkpoint: auth + CRUD service built; 120+ DSA problems | H10: 23 | I10: 26
A11: Month 7 | B11: 27–30 | C11: =IFERROR(INDEX('SDE Plan'!$C$6:$C$78,MATCH($H11,'SDE Plan'!$A$6:$A$78,0)),"—") -> 46489 | D11: =IFERROR(IF(INDEX('SDE Plan'!$F$6:$F$78,MATCH($H11,'SDE Plan'!$A$6:$A$78,0))=INDEX('SDE Plan'!$F$6:$F$78,MATCH($I11,'SDE Plan'!$A$6:$A$78,0)),INDEX('SDE Plan'!$F$6:$F$78,MATCH($H11,'SDE Plan'!$A$6:$A$78,0)),INDEX('SDE Plan'!$F$6:$F$78,MATCH($H11,'SDE Plan'!$A$6:$A$78,0))&" → "&INDEX('SDE Plan'!$F$6:$F$78,MATCH($I11,'SDE Plan'!$A$6:$A$78,0))),"—") -> Applied Design & Machine Coding → AI-First Backend Capstone Project – Primer | E11: =IFERROR(IF(INDEX('FullStack Plan'!$F$6:$F$78,MATCH($H11,'FullStack Plan'!$A$6:$A$78,0))=INDEX('FullStack Plan'!$F$6:$F$78,MATCH($I11,'FullStack Plan'!$A$6:$A$78,0)),INDEX('FullStack Plan'!$F$6:$F$78,MATCH($H11,'FullStack Plan'!$A$6:$A$78,0)),INDEX('FullStack Plan'!$F$6:$F$78,MATCH($H11,'FullStack Plan'!$A$6:$A$78,0))&" → "&INDEX('FullStack Plan'!$F$6:$F$78,MATCH($I11,'FullStack Plan'!$A$6:$A$78,0))),"—") -> React, TypeScript & Frontend Architecture – Deep Dive (incl. Next.js) → Foundations of AI-Assisted Full-Stack Development | F11: =(I11-H11+1)*Overview!$C$5 -> 80 | G11: Checkpoint: design patterns / advanced frontend applied in a real project | H11: 27 | I11: 30
A12: Month 8 | B12: 31–35 | C12: =IFERROR(INDEX('SDE Plan'!$C$6:$C$78,MATCH($H12,'SDE Plan'!$A$6:$A$78,0)),"—") -> 46517 | D12: =IFERROR(IF(INDEX('SDE Plan'!$F$6:$F$78,MATCH($H12,'SDE Plan'!$A$6:$A$78,0))=INDEX('SDE Plan'!$F$6:$F$78,MATCH($I12,'SDE Plan'!$A$6:$A$78,0)),INDEX('SDE Plan'!$F$6:$F$78,MATCH($H12,'SDE Plan'!$A$6:$A$78,0)),INDEX('SDE Plan'!$F$6:$F$78,MATCH($H12,'SDE Plan'!$A$6:$A$78,0))&" → "&INDEX('SDE Plan'!$F$6:$F$78,MATCH($I12,'SDE Plan'!$A$6:$A$78,0))),"—") -> AI-First Backend Capstone Project – Advance → Distributed System Design & AI-Integrated Architectures | E12: =IFERROR(IF(INDEX('FullStack Plan'!$F$6:$F$78,MATCH($H12,'FullStack Plan'!$A$6:$A$78,0))=INDEX('FullStack Plan'!$F$6:$F$78,MATCH($I12,'FullStack Plan'!$A$6:$A$78,0)),INDEX('FullStack Plan'!$F$6:$F$78,MATCH($H12,'FullStack Plan'!$A$6:$A$78,0)),INDEX('FullStack Plan'!$F$6:$F$78,MATCH($H12,'FullStack Plan'!$A$6:$A$78,0))&" → "&INDEX('FullStack Plan'!$F$6:$F$78,MATCH($I12,'FullStack Plan'!$A$6:$A$78,0))),"—") -> Full-Stack Capstone Project (suggested) → Intermediate DSA: AI-Assisted Problem Solving | F12: =(I12-H12+1)*Overview!$C$5 -> 100 | G12: Checkpoint: capstone feature-complete; first system-design write-up | H12: 31 | I12: 35
A13: Month 9 | B13: 36–39 | C13: =IFERROR(INDEX('SDE Plan'!$C$6:$C$78,MATCH($H13,'SDE Plan'!$A$6:$A$78,0)),"—") -> 46552 | D13: =IFERROR(IF(INDEX('SDE Plan'!$F$6:$F$78,MATCH($H13,'SDE Plan'!$A$6:$A$78,0))=INDEX('SDE Plan'!$F$6:$F$78,MATCH($I13,'SDE Plan'!$A$6:$A$78,0)),INDEX('SDE Plan'!$F$6:$F$78,MATCH($H13,'SDE Plan'!$A$6:$A$78,0)),INDEX('SDE Plan'!$F$6:$F$78,MATCH($H13,'SDE Plan'!$A$6:$A$78,0))&" → "&INDEX('SDE Plan'!$F$6:$F$78,MATCH($I13,'SDE Plan'!$A$6:$A$78,0))),"—") -> Distributed System Design & AI-Integrated Architectures → Mastering LastMile – Interview Simulation | E13: =IFERROR(IF(INDEX('FullStack Plan'!$F$6:$F$78,MATCH($H13,'FullStack Plan'!$A$6:$A$78,0))=INDEX('FullStack Plan'!$F$6:$F$78,MATCH($I13,'FullStack Plan'!$A$6:$A$78,0)),INDEX('FullStack Plan'!$F$6:$F$78,MATCH($H13,'FullStack Plan'!$A$6:$A$78,0)),INDEX('FullStack Plan'!$F$6:$F$78,MATCH($H13,'FullStack Plan'!$A$6:$A$78,0))&" → "&INDEX('FullStack Plan'!$F$6:$F$78,MATCH($I13,'FullStack Plan'!$A$6:$A$78,0))),"—") -> Intermediate DSA: AI-Assisted Problem Solving → Mastering LastMile – Interview Simulation | F13: =(I13-H13+1)*Overview!$C$5 -> 80 | G13: Final: capstone deployed, 3 mock interviews, resume & LinkedIn updated | H13: 36 | I13: 39

Sheet Timeline
A1: 🗓️ Timeline – Gantt view of the 39-week plan
A2: Bars are formulas: coloured = planned weeks, dark green = weeks marked Done. Skipped (Include? = No) modules show no bar.
A4: Track | B4: Module | C4: Start wk | D4: End wk | E4: Month 1 | I4: Month 2 | N4: Month 3 | R4: Month 4 | V4: Month 5 | AA4: Month 6 | AE4: Month 7 | AI4: Month 8 | AN4: Month 9
E5: 1 | F5: 2 | G5: 3 | H5: 4 | I5: 5 | J5: 6 | K5: 7 | L5: 8 | M5: 9 | N5: 10 | O5: 11 | P5: 12 | Q5: 13 | R5: 14 | S5: 15 | T5: 16 | U5: 17 | V5: 18 | W5: 19 | X5: 20 | Y5: 21 | Z5: 22 | AA5: 23 | AB5: 24 | AC5: 25 | AD5: 26 | AE5: 27 | AF5: 28 | AG5: 29 | AH5: 30 | AI5: 31 | AJ5: 32 | AK5: 33 | AL5: 34 | AM5: 35 | AN5: 36 | AO5: 37 | AP5: 38 | AQ5: 39
A6: 🧠 SDE TRACK
A7: SDE | B7: Programming Fundamentals – Thinking with AI: Logics, Loops & Control Flow | C7: =IF(COUNTIFS('SDE Plan'!$F$6:$F$78,$B7,'SDE Plan'!$B$6:$B$78,"Yes")=0,"",_xlfn.MINIFS('SDE Plan'!$A$6:$A$78,'SDE Plan'!$F$6:$F$78,$B7,'SDE Plan'!$B$6:$B$78,"Yes")) | D7: =IF(COUNTIFS('SDE Plan'!$F$6:$F$78,$B7,'SDE Plan'!$B$6:$B$78,"Yes")=0,"",_xlfn.MAXIFS('SDE Plan'!$A$6:$A$78,'SDE Plan'!$F$6:$F$78,$B7,'SDE Plan'!$B$6:$B$78,"Yes")) | E7: =IF($C7="","",IF(AND(E$5>=$C7,E$5<=$D7),IF(E$5<$C7+COUNTIFS('SDE Plan'!$F$6:$F$78,$B7,'SDE Plan'!$B$6:$B$78,"Yes",'SDE Plan'!$L$6:$L$78,"Done"),2,1),"")) | F7: =IF($C7="","",IF(AND(F$5>=$C7,F$5<=$D7),IF(F$5<$C7+COUNTIFS('SDE Plan'!$F$6:$F$78,$B7,'SDE Plan'!$B$6:$B$78,"Yes",'SDE Plan'!$L$6:$L$78,"Done"),2,1),"")) | G7: =IF($C7="","",IF(AND(G$5>=$C7,G$5<=$D7),IF(G$5<$C7+COUNTIFS('SDE Plan'!$F$6:$F$78,$B7,'SDE Plan'!$B$6:$B$78,"Yes",'SDE Plan'!$L$6:$L$78,"Done"),2,1),"")) | H7: =IF($C7="","",IF(AND(H$5>=$C7,H$5<=$D7),IF(H$5<$C7+COUNTIFS('SDE Plan'!$F$6:$F$78,$B7,'SDE Plan'!$B$6:$B$78,"Yes",'SDE Plan'!$L$6:$L$78,"Done"),2,1),"")) | I7: =IF($C7="","",IF(AND(I$5>=$C7,I$5<=$D7),IF(I$5<$C7+COUNTIFS('SDE Plan'!$F$6:$F$78,$B7,'SDE Plan'!$B$6:$B$78,"Yes",'SDE Plan'!$L$6:$L$78,"Done"),2,1),"")) | J7: =IF($C7="","",IF(AND(J$5>=$C7,J$5<=$D7),IF(J$5<$C7+COUNTIFS('SDE Plan'!$F$6:$F$78,$B7,'SDE Plan'!$B$6:$B$78,"Yes",'SDE Plan'!$L$6:$L$78,"Done"),2,1),"")) | K7: =IF($C7="","",IF(AND(K$5>=$C7,K$5<=$D7),IF(K$5<$C7+COUNTIFS('SDE Plan'!$F$6:$F$78,$B7,'SDE Plan'!$B$6:$B$78,"Yes",'SDE Plan'!$L$6:$L$78,"Done"),2,1),"")) | L7: =IF($C7="","",IF(AND(L$5>=$C7,L$5<=$D7),IF(L$5<$C7+COUNTIFS('SDE Plan'!$F$6:$F$78,$B7,'SDE Plan'!$B$6:$B$78,"Yes",'SDE Plan'!$L$6:$L$78,"Done"),2,1),"")) | ... AQ7: =IF($C7="","",IF(AND(AQ$5>=$C7,AQ$5<=$D7),IF(AQ$5<$C7+COUNTIFS('SDE Plan'!$F$6:$F$78,$B7,'SDE Plan'!$B$6:$B$78,"Yes",'SDE Plan'!$L$6:$L$78,"Done"),2,1),""))
A8: SDE | B8: Programming Fundamentals – Code Smarter with AI: Functions & Arrays | C8: =IF(COUNTIFS('SDE Plan'!$F$6:$F$78,$B8,'SDE Plan'!$B$6:$B$78,"Yes")=0,"",_xlfn.MINIFS('SDE Plan'!$A$6:$A$78,'SDE Plan'!$F$6:$F$78,$B8,'SDE Plan'!$B$6:$B$78,"Yes")) | D8: =IF(COUNTIFS('SDE Plan'!$F$6:$F$78,$B8,'SDE Plan'!$B$6:$B$78,"Yes")=0,"",_xlfn.MAXIFS('SDE Plan'!$A$6:$A$78,'SDE Plan'!$F$6:$F$78,$B8,'SDE Plan'!$B$6:$B$78,"Yes")) | E8: =IF($C8="","",IF(AND(E$5>=$C8,E$5<=$D8),IF(E$5<$C8+COUNTIFS('SDE Plan'!$F$6:$F$78,$B8,'SDE Plan'!$B$6:$B$78,"Yes",'SDE Plan'!$L$6:$L$78,"Done"),2,1),"")) | F8: =IF($C8="","",IF(AND(F$5>=$C8,F$5<=$D8),IF(F$5<$C8+COUNTIFS('SDE Plan'!$F$6:$F$78,$B8,'SDE Plan'!$B$6:$B$78,"Yes",'SDE Plan'!$L$6:$L$78,"Done"),2,1),"")) | G8: =IF($C8="","",IF(AND(G$5>=$C8,G$5<=$D8),IF(G$5<$C8+COUNTIFS('SDE Plan'!$F$6:$F$78,$B8,'SDE Plan'!$B$6:$B$78,"Yes",'SDE Plan'!$L$6:$L$78,"Done"),2,1),"")) | H8: =IF($C8="","",IF(AND(H$5>=$C8,H$5<=$D8),IF(H$5<$C8+COUNTIFS('SDE Plan'!$F$6:$F$78,$B8,'SDE Plan'!$B$6:$B$78,"Yes",'SDE Plan'!$L$6:$L$78,"Done"),2,1),"")) | I8: =IF($C8="","",IF(AND(I$5>=$C8,I$5<=$D8),IF(I$5<$C8+COUNTIFS('SDE Plan'!$F$6:$F$78,$B8,'SDE Plan'!$B$6:$B$78,"Yes",'SDE Plan'!$L$6:$L$78,"Done"),2,1),"")) | J8: =IF($C8="","",IF(AND(J$5>=$C8,J$5<=$D8),IF(J$5<$C8+COUNTIFS('SDE Plan'!$F$6:$F$78,$B8,'SDE Plan'!$B$6:$B$78,"Yes",'SDE Plan'!$L$6:$L$78,"Done"),2,1),"")) | K8: =IF($C8="","",IF(AND(K$5>=$C8,K$5<=$D8),IF(K$5<$C8+COUNTIFS('SDE Plan'!$F$6:$F$78,$B8,'SDE Plan'!$B$6:$B$78,"Yes",'SDE Plan'!$L$6:$L$78,"Done"),2,1),"")) | L8: =IF($C8="","",IF(AND(L$5>=$C8,L$5<=$D8),IF(L$5<$C8+COUNTIFS('SDE Plan'!$F$6:$F$78,$B8,'SDE Plan'!$B$6:$B$78,"Yes",'SDE Plan'!$L$6:$L$78,"Done"),2,1),"")) | ... AQ8: =IF($C8="","",IF(AND(AQ$5>=$C8,AQ$5<=$D8),IF(AQ$5<$C8+COUNTIFS('SDE Plan'!$F$6:$F$78,$B8,'SDE Plan'!$B$6:$B$78,"Yes",'SDE Plan'!$L$6:$L$78,"Done"),2,1),""))
A9: SDE | B9: Intermediate DSA: AI-Assisted Problem Solving | C9: =IF(COUNTIFS('SDE Plan'!$F$6:$F$78,$B9,'SDE Plan'!$B$6:$B$78,"Yes")=0,"",_xlfn.MINIFS('SDE Plan'!$A$6:$A$78,'SDE Plan'!$F$6:$F$78,$B9,'SDE Plan'!$B$6:$B$78,"Yes")) -> 1 | D9: =IF(COUNTIFS('SDE Plan'!$F$6:$F$78,$B9,'SDE Plan'!$B$6:$B$78,"Yes")=0,"",_xlfn.MAXIFS('SDE Plan'!$A$6:$A$78,'SDE Plan'!$F$6:$F$78,$B9,'SDE Plan'!$B$6:$B$78,"Yes")) -> 2 | E9: =IF($C9="","",IF(AND(E$5>=$C9,E$5<=$D9),IF(E$5<$C9+COUNTIFS('SDE Plan'!$F$6:$F$78,$B9,'SDE Plan'!$B$6:$B$78,"Yes",'SDE Plan'!$L$6:$L$78,"Done"),2,1),"")) -> 1 | F9: =IF($C9="","",IF(AND(F$5>=$C9,F$5<=$D9),IF(F$5<$C9+COUNTIFS('SDE Plan'!$F$6:$F$78,$B9,'SDE Plan'!$B$6:$B$78,"Yes",'SDE Plan'!$L$6:$L$78,"Done"),2,1),"")) -> 1 | G9: =IF($C9="","",IF(AND(G$5>=$C9,G$5<=$D9),IF(G$5<$C9+COUNTIFS('SDE Plan'!$F$6:$F$78,$B9,'SDE Plan'!$B$6:$B$78,"Yes",'SDE Plan'!$L$6:$L$78,"Done"),2,1),"")) | H9: =IF($C9="","",IF(AND(H$5>=$C9,H$5<=$D9),IF(H$5<$C9+COUNTIFS('SDE Plan'!$F$6:$F$78,$B9,'SDE Plan'!$B$6:$B$78,"Yes",'SDE Plan'!$L$6:$L$78,"Done"),2,1),"")) | I9: =IF($C9="","",IF(AND(I$5>=$C9,I$5<=$D9),IF(I$5<$C9+COUNTIFS('SDE Plan'!$F$6:$F$78,$B9,'SDE Plan'!$B$6:$B$78,"Yes",'SDE Plan'!$L$6:$L$78,"Done"),2,1),"")) | J9: =IF($C9="","",IF(AND(J$5>=$C9,J$5<=$D9),IF(J$5<$C9+COUNTIFS('SDE Plan'!$F$6:$F$78,$B9,'SDE Plan'!$B$6:$B$78,"Yes",'SDE Plan'!$L$6:$L$78,"Done"),2,1),"")) | K9: =IF($C9="","",IF(AND(K$5>=$C9,K$5<=$D9),IF(K$5<$C9+COUNTIFS('SDE Plan'!$F$6:$F$78,$B9,'SDE Plan'!$B$6:$B$78,"Yes",'SDE Plan'!$L$6:$L$78,"Done"),2,1),"")) | L9: =IF($C9="","",IF(AND(L$5>=$C9,L$5<=$D9),IF(L$5<$C9+COUNTIFS('SDE Plan'!$F$6:$F$78,$B9,'SDE Plan'!$B$6:$B$78,"Yes",'SDE Plan'!$L$6:$L$78,"Done"),2,1),"")) | ... AQ9: =IF($C9="","",IF(AND(AQ$5>=$C9,AQ$5<=$D9),IF(AQ$5<$C9+COUNTIFS('SDE Plan'!$F$6:$F$78,$B9,'SDE Plan'!$B$6:$B$78,"Yes",'SDE Plan'!$L$6:$L$78,"Done"),2,1),""))
A10: SDE | B10: Agentic AI: From Talking to AI to Building One | C10: =IF(COUNTIFS('SDE Plan'!$F$6:$F$78,$B10,'SDE Plan'!$B$6:$B$78,"Yes")=0,"",_xlfn.MINIFS('SDE Plan'!$A$6:$A$78,'SDE Plan'!$F$6:$F$78,$B10,'SDE Plan'!$B$6:$B$78,"Yes")) -> 3 | D10: =IF(COUNTIFS('SDE Plan'!$F$6:$F$78,$B10,'SDE Plan'!$B$6:$B$78,"Yes")=0,"",_xlfn.MAXIFS('SDE Plan'!$A$6:$A$78,'SDE Plan'!$F$6:$F$78,$B10,'SDE Plan'!$B$6:$B$78,"Yes")) -> 4 | E10: =IF($C10="","",IF(AND(E$5>=$C10,E$5<=$D10),IF(E$5<$C10+COUNTIFS('SDE Plan'!$F$6:$F$78,$B10,'SDE Plan'!$B$6:$B$78,"Yes",'SDE Plan'!$L$6:$L$78,"Done"),2,1),"")) | F10: =IF($C10="","",IF(AND(F$5>=$C10,F$5<=$D10),IF(F$5<$C10+COUNTIFS('SDE Plan'!$F$6:$F$78,$B10,'SDE Plan'!$B$6:$B$78,"Yes",'SDE Plan'!$L$6:$L$78,"Done"),2,1),"")) | G10: =IF($C10="","",IF(AND(G$5>=$C10,G$5<=$D10),IF(G$5<$C10+COUNTIFS('SDE Plan'!$F$6:$F$78,$B10,'SDE Plan'!$B$6:$B$78,"Yes",'SDE Plan'!$L$6:$L$78,"Done"),2,1),"")) -> 1 | H10: =IF($C10="","",IF(AND(H$5>=$C10,H$5<=$D10),IF(H$5<$C10+COUNTIFS('SDE Plan'!$F$6:$F$78,$B10,'SDE Plan'!$B$6:$B$78,"Yes",'SDE Plan'!$L$6:$L$78,"Done"),2,1),"")) -> 1 | I10: =IF($C10="","",IF(AND(I$5>=$C10,I$5<=$D10),IF(I$5<$C10+COUNTIFS('SDE Plan'!$F$6:$F$78,$B10,'SDE Plan'!$B$6:$B$78,"Yes",'SDE Plan'!$L$6:$L$78,"Done"),2,1),"")) | J10: =IF($C10="","",IF(AND(J$5>=$C10,J$5<=$D10),IF(J$5<$C10+COUNTIFS('SDE Plan'!$F$6:$F$78,$B10,'SDE Plan'!$B$6:$B$78,"Yes",'SDE Plan'!$L$6:$L$78,"Done"),2,1),"")) | K10: =IF($C10="","",IF(AND(K$5>=$C10,K$5<=$D10),IF(K$5<$C10+COUNTIFS('SDE Plan'!$F$6:$F$78,$B10,'SDE Plan'!$B$6:$B$78,"Yes",'SDE Plan'!$L$6:$L$78,"Done"),2,1),"")) | L10: =IF($C10="","",IF(AND(L$5>=$C10,L$5<=$D10),IF(L$5<$C10+COUNTIFS('SDE Plan'!$F$6:$F$78,$B10,'SDE Plan'!$B$6:$B$78,"Yes",'SDE Plan'!$L$6:$L$78,"Done"),2,1),"")) | ... AQ10: =IF($C10="","",IF(AND(AQ$5>=$C10,AQ$5<=$D10),IF(AQ$5<$C10+COUNTIFS('SDE Plan'!$F$6:$F$78,$B10,'SDE Plan'!$B$6:$B$78,"Yes",'SDE Plan'!$L$6:$L$78,"Done"),2,1),""))
A11: SDE | B11: Advanced DSA: Foundations – Core Techniques & Optimization | C11: =IF(COUNTIFS('SDE Plan'!$F$6:$F$78,$B11,'SDE Plan'!$B$6:$B$78,"Yes")=0,"",_xlfn.MINIFS('SDE Plan'!$A$6:$A$78,'SDE Plan'!$F$6:$F$78,$B11,'SDE Plan'!$B$6:$B$78,"Yes")) -> 5 | D11: =IF(COUNTIFS('SDE Plan'!$F$6:$F$78,$B11,'SDE Plan'!$B$6:$B$78,"Yes")=0,"",_xlfn.MAXIFS('SDE Plan'!$A$6:$A$78,'SDE Plan'!$F$6:$F$78,$B11,'SDE Plan'!$B$6:$B$78,"Yes")) -> 7 | E11: =IF($C11="","",IF(AND(E$5>=$C11,E$5<=$D11),IF(E$5<$C11+COUNTIFS('SDE Plan'!$F$6:$F$78,$B11,'SDE Plan'!$B$6:$B$78,"Yes",'SDE Plan'!$L$6:$L$78,"Done"),2,1),"")) | F11: =IF($C11="","",IF(AND(F$5>=$C11,F$5<=$D11),IF(F$5<$C11+COUNTIFS('SDE Plan'!$F$6:$F$78,$B11,'SDE Plan'!$B$6:$B$78,"Yes",'SDE Plan'!$L$6:$L$78,"Done"),2,1),"")) | G11: =IF($C11="","",IF(AND(G$5>=$C11,G$5<=$D11),IF(G$5<$C11+COUNTIFS('SDE Plan'!$F$6:$F$78,$B11,'SDE Plan'!$B$6:$B$78,"Yes",'SDE Plan'!$L$6:$L$78,"Done"),2,1),"")) | H11: =IF($C11="","",IF(AND(H$5>=$C11,H$5<=$D11),IF(H$5<$C11+COUNTIFS('SDE Plan'!$F$6:$F$78,$B11,'SDE Plan'!$B$6:$B$78,"Yes",'SDE Plan'!$L$6:$L$78,"Done"),2,1),"")) | I11: =IF($C11="","",IF(AND(I$5>=$C11,I$5<=$D11),IF(I$5<$C11+COUNTIFS('SDE Plan'!$F$6:$F$78,$B11,'SDE Plan'!$B$6:$B$78,"Yes",'SDE Plan'!$L$6:$L$78,"Done"),2,1),"")) -> 1 | J11: =IF($C11="","",IF(AND(J$5>=$C11,J$5<=$D11),IF(J$5<$C11+COUNTIFS('SDE Plan'!$F$6:$F$78,$B11,'SDE Plan'!$B$6:$B$78,"Yes",'SDE Plan'!$L$6:$L$78,"Done"),2,1),"")) -> 1 | K11: =IF($C11="","",IF(AND(K$5>=$C11,K$5<=$D11),IF(K$5<$C11+COUNTIFS('SDE Plan'!$F$6:$F$78,$B11,'SDE Plan'!$B$6:$B$78,"Yes",'SDE Plan'!$L$6:$L$78,"Done"),2,1),"")) -> 1 | L11: =IF($C11="","",IF(AND(L$5>=$C11,L$5<=$D11),IF(L$5<$C11+COUNTIFS('SDE Plan'!$F$6:$F$78,$B11,'SDE Plan'!$B$6:$B$78,"Yes",'SDE Plan'!$L$6:$L$78,"Done"),2,1),"")) | ... AQ11: =IF($C11="","",IF(AND(AQ$5>=$C11,AQ$5<=$D11),IF(AQ$5<$C11+COUNTIFS('SDE Plan'!$F$6:$F$78,$B11,'SDE Plan'!$B$6:$B$78,"Yes",'SDE Plan'!$L$6:$L$78,"Done"),2,1),""))
A12: SDE | B12: Advanced DSA: Linear & Non-Linear Structures | C12: =IF(COUNTIFS('SDE Plan'!$F$6:$F$78,$B12,'SDE Plan'!$B$6:$B$78,"Yes")=0,"",_xlfn.MINIFS('SDE Plan'!$A$6:$A$78,'SDE Plan'!$F$6:$F$78,$B12,'SDE Plan'!$B$6:$B$78,"Yes")) -> 8 | D12: =IF(COUNTIFS('SDE Plan'!$F$6:$F$78,$B12,'SDE Plan'!$B$6:$B$78,"Yes")=0,"",_xlfn.MAXIFS('SDE Plan'!$A$6:$A$78,'SDE Plan'!$F$6:$F$78,$B12,'SDE Plan'!$B$6:$B$78,"Yes")) -> 10 | E12: =IF($C12="","",IF(AND(E$5>=$C12,E$5<=$D12),IF(E$5<$C12+COUNTIFS('SDE Plan'!$F$6:$F$78,$B12,'SDE Plan'!$B$6:$B$78,"Yes",'SDE Plan'!$L$6:$L$78,"Done"),2,1),"")) | F12: =IF($C12="","",IF(AND(F$5>=$C12,F$5<=$D12),IF(F$5<$C12+COUNTIFS('SDE Plan'!$F$6:$F$78,$B12,'SDE Plan'!$B$6:$B$78,"Yes",'SDE Plan'!$L$6:$L$78,"Done"),2,1),"")) | G12: =IF($C12="","",IF(AND(G$5>=$C12,G$5<=$D12),IF(G$5<$C12+COUNTIFS('SDE Plan'!$F$6:$F$78,$B12,'SDE Plan'!$B$6:$B$78,"Yes",'SDE Plan'!$L$6:$L$78,"Done"),2,1),"")) | H12: =IF($C12="","",IF(AND(H$5>=$C12,H$5<=$D12),IF(H$5<$C12+COUNTIFS('SDE Plan'!$F$6:$F$78,$B12,'SDE Plan'!$B$6:$B$78,"Yes",'SDE Plan'!$L$6:$L$78,"Done"),2,1),"")) | I12: =IF($C12="","",IF(AND(I$5>=$C12,I$5<=$D12),IF(I$5<$C12+COUNTIFS('SDE Plan'!$F$6:$F$78,$B12,'SDE Plan'!$B$6:$B$78,"Yes",'SDE Plan'!$L$6:$L$78,"Done"),2,1),"")) | J12: =IF($C12="","",IF(AND(J$5>=$C12,J$5<=$D12),IF(J$5<$C12+COUNTIFS('SDE Plan'!$F$6:$F$78,$B12,'SDE Plan'!$B$6:$B$78,"Yes",'SDE Plan'!$L$6:$L$78,"Done"),2,1),"")) | K12: =IF($C12="","",IF(AND(K$5>=$C12,K$5<=$D12),IF(K$5<$C12+COUNTIFS('SDE Plan'!$F$6:$F$78,$B12,'SDE Plan'!$B$6:$B$78,"Yes",'SDE Plan'!$L$6:$L$78,"Done"),2,1),"")) | L12: =IF($C12="","",IF(AND(L$5>=$C12,L$5<=$D12),IF(L$5<$C12+COUNTIFS('SDE Plan'!$F$6:$F$78,$B12,'SDE Plan'!$B$6:$B$78,"Yes",'SDE Plan'!$L$6:$L$78,"Done"),2,1),"")) -> 1 | ... AQ12: =IF($C12="","",IF(AND(AQ$5>=$C12,AQ$5<=$D12),IF(AQ$5<$C12+COUNTIFS('SDE Plan'!$F$6:$F$78,$B12,'SDE Plan'!$B$6:$B$78,"Yes",'SDE Plan'!$L$6:$L$78,"Done"),2,1),""))
A13: SDE | B13: Advanced DSA: Backtracking & Advanced Trees | C13: =IF(COUNTIFS('SDE Plan'!$F$6:$F$78,$B13,'SDE Plan'!$B$6:$B$78,"Yes")=0,"",_xlfn.MINIFS('SDE Plan'!$A$6:$A$78,'SDE Plan'!$F$6:$F$78,$B13,'SDE Plan'!$B$6:$B$78,"Yes")) -> 11 | D13: =IF(COUNTIFS('SDE Plan'!$F$6:$F$78,$B13,'SDE Plan'!$B$6:$B$78,"Yes")=0,"",_xlfn.MAXIFS('SDE Plan'!$A$6:$A$78,'SDE Plan'!$F$6:$F$78,$B13,'SDE Plan'!$B$6:$B$78,"Yes")) -> 13 | E13: =IF($C13="","",IF(AND(E$5>=$C13,E$5<=$D13),IF(E$5<$C13+COUNTIFS('SDE Plan'!$F$6:$F$78,$B13,'SDE Plan'!$B$6:$B$78,"Yes",'SDE Plan'!$L$6:$L$78,"Done"),2,1),"")) | F13: =IF($C13="","",IF(AND(F$5>=$C13,F$5<=$D13),IF(F$5<$C13+COUNTIFS('SDE Plan'!$F$6:$F$78,$B13,'SDE Plan'!$B$6:$B$78,"Yes",'SDE Plan'!$L$6:$L$78,"Done"),2,1),"")) | G13: =IF($C13="","",IF(AND(G$5>=$C13,G$5<=$D13),IF(G$5<$C13+COUNTIFS('SDE Plan'!$F$6:$F$78,$B13,'SDE Plan'!$B$6:$B$78,"Yes",'SDE Plan'!$L$6:$L$78,"Done"),2,1),"")) | H13: =IF($C13="","",IF(AND(H$5>=$C13,H$5<=$D13),IF(H$5<$C13+COUNTIFS('SDE Plan'!$F$6:$F$78,$B13,'SDE Plan'!$B$6:$B$78,"Yes",'SDE Plan'!$L$6:$L$78,"Done"),2,1),"")) | I13: =IF($C13="","",IF(AND(I$5>=$C13,I$5<=$D13),IF(I$5<$C13+COUNTIFS('SDE Plan'!$F$6:$F$78,$B13,'SDE Plan'!$B$6:$B$78,"Yes",'SDE Plan'!$L$6:$L$78,"Done"),2,1),"")) | J13: =IF($C13="","",IF(AND(J$5>=$C13,J$5<=$D13),IF(J$5<$C13+COUNTIFS('SDE Plan'!$F$6:$F$78,$B13,'SDE Plan'!$B$6:$B$78,"Yes",'SDE Plan'!$L$6:$L$78,"Done"),2,1),"")) | K13: =IF($C13="","",IF(AND(K$5>=$C13,K$5<=$D13),IF(K$5<$C13+COUNTIFS('SDE Plan'!$F$6:$F$78,$B13,'SDE Plan'!$B$6:$B$78,"Yes",'SDE Plan'!$L$6:$L$78,"Done"),2,1),"")) | L13: =IF($C13="","",IF(AND(L$5>=$C13,L$5<=$D13),IF(L$5<$C13+COUNTIFS('SDE Plan'!$F$6:$F$78,$B13,'SDE Plan'!$B$6:$B$78,"Yes",'SDE Plan'!$L$6:$L$78,"Done"),2,1),"")) | ... AQ13: =IF($C13="","",IF(AND(AQ$5>=$C13,AQ$5<=$D13),IF(AQ$5<$C13+COUNTIFS('SDE Plan'!$F$6:$F$78,$B13,'SDE Plan'!$B$6:$B$78,"Yes",'SDE Plan'!$L$6:$L$78,"Done"),2,1),""))
A14: SDE | B14: Advanced DSA: DP, Heaps & Graphs – Crack It with AI Edge | C14: =IF(COUNTIFS('SDE Plan'!$F$6:$F$78,$B14,'SDE Plan'!$B$6:$B$78,"Yes")=0,"",_xlfn.MINIFS('SDE Plan'!$A$6:$A$78,'SDE Plan'!$F$6:$F$78,$B14,'SDE Plan'!$B$6:$B$78,"Yes")) -> 14 | D14: =IF(COUNTIFS('SDE Plan'!$F$6:$F$78,$B14,'SDE Plan'!$B$6:$B$78,"Yes")=0,"",_xlfn.MAXIFS('SDE Plan'!$A$6:$A$78,'SDE Plan'!$F$6:$F$78,$B14,'SDE Plan'!$B$6:$B$78,"Yes")) -> 17 | E14: =IF($C14="","",IF(AND(E$5>=$C14,E$5<=$D14),IF(E$5<$C14+COUNTIFS('SDE Plan'!$F$6:$F$78,$B14,'SDE Plan'!$B$6:$B$78,"Yes",'SDE Plan'!$L$6:$L$78,"Done"),2,1),"")) | F14: =IF($C14="","",IF(AND(F$5>=$C14,F$5<=$D14),IF(F$5<$C14+COUNTIFS('SDE Plan'!$F$6:$F$78,$B14,'SDE Plan'!$B$6:$B$78,"Yes",'SDE Plan'!$L$6:$L$78,"Done"),2,1),"")) | G14: =IF($C14="","",IF(AND(G$5>=$C14,G$5<=$D14),IF(G$5<$C14+COUNTIFS('SDE Plan'!$F$6:$F$78,$B14,'SDE Plan'!$B$6:$B$78,"Yes",'SDE Plan'!$L$6:$L$78,"Done"),2,1),"")) | H14: =IF($C14="","",IF(AND(H$5>=$C14,H$5<=$D14),IF(H$5<$C14+COUNTIFS('SDE Plan'!$F$6:$F$78,$B14,'SDE Plan'!$B$6:$B$78,"Yes",'SDE Plan'!$L$6:$L$78,"Done"),2,1),"")) | I14: =IF($C14="","",IF(AND(I$5>=$C14,I$5<=$D14),IF(I$5<$C14+COUNTIFS('SDE Plan'!$F$6:$F$78,$B14,'SDE Plan'!$B$6:$B$78,"Yes",'SDE Plan'!$L$6:$L$78,"Done"),2,1),"")) | J14: =IF($C14="","",IF(AND(J$5>=$C14,J$5<=$D14),IF(J$5<$C14+COUNTIFS('SDE Plan'!$F$6:$F$78,$B14,'SDE Plan'!$B$6:$B$78,"Yes",'SDE Plan'!$L$6:$L$78,"Done"),2,1),"")) | K14: =IF($C14="","",IF(AND(K$5>=$C14,K$5<=$D14),IF(K$5<$C14+COUNTIFS('SDE Plan'!$F$6:$F$78,$B14,'SDE Plan'!$B$6:$B$78,"Yes",'SDE Plan'!$L$6:$L$78,"Done"),2,1),"")) | L14: =IF($C14="","",IF(AND(L$5>=$C14,L$5<=$D14),IF(L$5<$C14+COUNTIFS('SDE Plan'!$F$6:$F$78,$B14,'SDE Plan'!$B$6:$B$78,"Yes",'SDE Plan'!$L$6:$L$78,"Done"),2,1),"")) | ... AQ14: =IF($C14="","",IF(AND(AQ$5>=$C14,AQ$5<=$D14),IF(AQ$5<$C14+COUNTIFS('SDE Plan'!$F$6:$F$78,$B14,'SDE Plan'!$B$6:$B$78,"Yes",'SDE Plan'!$L$6:$L$78,"Done"),2,1),""))
A15: SDE | B15: Databases & SQL | C15: =IF(COUNTIFS('SDE Plan'!$F$6:$F$78,$B15,'SDE Plan'!$B$6:$B$78,"Yes")=0,"",_xlfn.MINIFS('SDE Plan'!$A$6:$A$78,'SDE Plan'!$F$6:$F$78,$B15,'SDE Plan'!$B$6:$B$78,"Yes")) -> 18 | D15: =IF(COUNTIFS('SDE Plan'!$F$6:$F$78,$B15,'SDE Plan'!$B$6:$B$78,"Yes")=0,"",_xlfn.MAXIFS('SDE Plan'!$A$6:$A$78,'SDE Plan'!$F$6:$F$78,$B15,'SDE Plan'!$B$6:$B$78,"Yes")) -> 19 | E15: =IF($C15="","",IF(AND(E$5>=$C15,E$5<=$D15),IF(E$5<$C15+COUNTIFS('SDE Plan'!$F$6:$F$78,$B15,'SDE Plan'!$B$6:$B$78,"Yes",'SDE Plan'!$L$6:$L$78,"Done"),2,1),"")) | F15: =IF($C15="","",IF(AND(F$5>=$C15,F$5<=$D15),IF(F$5<$C15+COUNTIFS('SDE Plan'!$F$6:$F$78,$B15,'SDE Plan'!$B$6:$B$78,"Yes",'SDE Plan'!$L$6:$L$78,"Done"),2,1),"")) | G15: =IF($C15="","",IF(AND(G$5>=$C15,G$5<=$D15),IF(G$5<$C15+COUNTIFS('SDE Plan'!$F$6:$F$78,$B15,'SDE Plan'!$B$6:$B$78,"Yes",'SDE Plan'!$L$6:$L$78,"Done"),2,1),"")) | H15: =IF($C15="","",IF(AND(H$5>=$C15,H$5<=$D15),IF(H$5<$C15+COUNTIFS('SDE Plan'!$F$6:$F$78,$B15,'SDE Plan'!$B$6:$B$78,"Yes",'SDE Plan'!$L$6:$L$78,"Done"),2,1),"")) | I15: =IF($C15="","",IF(AND(I$5>=$C15,I$5<=$D15),IF(I$5<$C15+COUNTIFS('SDE Plan'!$F$6:$F$78,$B15,'SDE Plan'!$B$6:$B$78,"Yes",'SDE Plan'!$L$6:$L$78,"Done"),2,1),"")) | J15: =IF($C15="","",IF(AND(J$5>=$C15,J$5<=$D15),IF(J$5<$C15+COUNTIFS('SDE Plan'!$F$6:$F$78,$B15,'SDE Plan'!$B$6:$B$78,"Yes",'SDE Plan'!$L$6:$L$78,"Done"),2,1),"")) | K15: =IF($C15="","",IF(AND(K$5>=$C15,K$5<=$D15),IF(K$5<$C15+COUNTIFS('SDE Plan'!$F$6:$F$78,$B15,'SDE Plan'!$B$6:$B$78,"Yes",'SDE Plan'!$L$6:$L$78,"Done"),2,1),"")) | L15: =IF($C15="","",IF(AND(L$5>=$C15,L$5<=$D15),IF(L$5<$C15+COUNTIFS('SDE Plan'!$F$6:$F$78,$B15,'SDE Plan'!$B$6:$B$78,"Yes",'SDE Plan'!$L$6:$L$78,"Done"),2,1),"")) | ... AQ15: =IF($C15="","",IF(AND(AQ$5>=$C15,AQ$5<=$D15),IF(AQ$5<$C15+COUNTIFS('SDE Plan'!$F$6:$F$78,$B15,'SDE Plan'!$B$6:$B$78,"Yes",'SDE Plan'!$L$6:$L$78,"Done"),2,1),""))
A16: SDE | B16: Foundations of Object-Oriented Design & Scalable Systems | C16: =IF(COUNTIFS('SDE Plan'!$F$6:$F$78,$B16,'SDE Plan'!$B$6:$B$78,"Yes")=0,"",_xlfn.MINIFS('SDE Plan'!$A$6:$A$78,'SDE Plan'!$F$6:$F$78,$B16,'SDE Plan'!$B$6:$B$78,"Yes")) -> 20 | D16: =IF(COUNTIFS('SDE Plan'!$F$6:$F$78,$B16,'SDE Plan'!$B$6:$B$78,"Yes")=0,"",_xlfn.MAXIFS('SDE Plan'!$A$6:$A$78,'SDE Plan'!$F$6:$F$78,$B16,'SDE Plan'!$B$6:$B$78,"Yes")) -> 22 | E16: =IF($C16="","",IF(AND(E$5>=$C16,E$5<=$D16),IF(E$5<$C16+COUNTIFS('SDE Plan'!$F$6:$F$78,$B16,'SDE Plan'!$B$6:$B$78,"Yes",'SDE Plan'!$L$6:$L$78,"Done"),2,1),"")) | F16: =IF($C16="","",IF(AND(F$5>=$C16,F$5<=$D16),IF(F$5<$C16+COUNTIFS('SDE Plan'!$F$6:$F$78,$B16,'SDE Plan'!$B$6:$B$78,"Yes",'SDE Plan'!$L$6:$L$78,"Done"),2,1),"")) | G16: =IF($C16="","",IF(AND(G$5>=$C16,G$5<=$D16),IF(G$5<$C16+COUNTIFS('SDE Plan'!$F$6:$F$78,$B16,'SDE Plan'!$B$6:$B$78,"Yes",'SDE Plan'!$L$6:$L$78,"Done"),2,1),"")) | H16: =IF($C16="","",IF(AND(H$5>=$C16,H$5<=$D16),IF(H$5<$C16+COUNTIFS('SDE Plan'!$F$6:$F$78,$B16,'SDE Plan'!$B$6:$B$78,"Yes",'SDE Plan'!$L$6:$L$78,"Done"),2,1),"")) | I16: =IF($C16="","",IF(AND(I$5>=$C16,I$5<=$D16),IF(I$5<$C16+COUNTIFS('SDE Plan'!$F$6:$F$78,$B16,'SDE Plan'!$B$6:$B$78,"Yes",'SDE Plan'!$L$6:$L$78,"Done"),2,1),"")) | J16: =IF($C16="","",IF(AND(J$5>=$C16,J$5<=$D16),IF(J$5<$C16+COUNTIFS('SDE Plan'!$F$6:$F$78,$B16,'SDE Plan'!$B$6:$B$78,"Yes",'SDE Plan'!$L$6:$L$78,"Done"),2,1),"")) | K16: =IF($C16="","",IF(AND(K$5>=$C16,K$5<=$D16),IF(K$5<$C16+COUNTIFS('SDE Plan'!$F$6:$F$78,$B16,'SDE Plan'!$B$6:$B$78,"Yes",'SDE Plan'!$L$6:$L$78,"Done"),2,1),"")) | L16: =IF($C16="","",IF(AND(L$5>=$C16,L$5<=$D16),IF(L$5<$C16+COUNTIFS('SDE Plan'!$F$6:$F$78,$B16,'SDE Plan'!$B$6:$B$78,"Yes",'SDE Plan'!$L$6:$L$78,"Done"),2,1),"")) | ... AQ16: =IF($C16="","",IF(AND(AQ$5>=$C16,AQ$5<=$D16),IF(AQ$5<$C16+COUNTIFS('SDE Plan'!$F$6:$F$78,$B16,'SDE Plan'!$B$6:$B$78,"Yes",'SDE Plan'!$L$6:$L$78,"Done"),2,1),""))
A17: SDE | B17: Design Principles & Patterns for Extensible Systems | C17: =IF(COUNTIFS('SDE Plan'!$F$6:$F$78,$B17,'SDE Plan'!$B$6:$B$78,"Yes")=0,"",_xlfn.MINIFS('SDE Plan'!$A$6:$A$78,'SDE Plan'!$F$6:$F$78,$B17,'SDE Plan'!$B$6:$B$78,"Yes")) -> 23 | D17: =IF(COUNTIFS('SDE Plan'!$F$6:$F$78,$B17,'SDE Plan'!$B$6:$B$78,"Yes")=0,"",_xlfn.MAXIFS('SDE Plan'!$A$6:$A$78,'SDE Plan'!$F$6:$F$78,$B17,'SDE Plan'!$B$6:$B$78,"Yes")) -> 24 | E17: =IF($C17="","",IF(AND(E$5>=$C17,E$5<=$D17),IF(E$5<$C17+COUNTIFS('SDE Plan'!$F$6:$F$78,$B17,'SDE Plan'!$B$6:$B$78,"Yes",'SDE Plan'!$L$6:$L$78,"Done"),2,1),"")) | F17: =IF($C17="","",IF(AND(F$5>=$C17,F$5<=$D17),IF(F$5<$C17+COUNTIFS('SDE Plan'!$F$6:$F$78,$B17,'SDE Plan'!$B$6:$B$78,"Yes",'SDE Plan'!$L$6:$L$78,"Done"),2,1),"")) | G17: =IF($C17="","",IF(AND(G$5>=$C17,G$5<=$D17),IF(G$5<$C17+COUNTIFS('SDE Plan'!$F$6:$F$78,$B17,'SDE Plan'!$B$6:$B$78,"Yes",'SDE Plan'!$L$6:$L$78,"Done"),2,1),"")) | H17: =IF($C17="","",IF(AND(H$5>=$C17,H$5<=$D17),IF(H$5<$C17+COUNTIFS('SDE Plan'!$F$6:$F$78,$B17,'SDE Plan'!$B$6:$B$78,"Yes",'SDE Plan'!$L$6:$L$78,"Done"),2,1),"")) | I17: =IF($C17="","",IF(AND(I$5>=$C17,I$5<=$D17),IF(I$5<$C17+COUNTIFS('SDE Plan'!$F$6:$F$78,$B17,'SDE Plan'!$B$6:$B$78,"Yes",'SDE Plan'!$L$6:$L$78,"Done"),2,1),"")) | J17: =IF($C17="","",IF(AND(J$5>=$C17,J$5<=$D17),IF(J$5<$C17+COUNTIFS('SDE Plan'!$F$6:$F$78,$B17,'SDE Plan'!$B$6:$B$78,"Yes",'SDE Plan'!$L$6:$L$78,"Done"),2,1),"")) | K17: =IF($C17="","",IF(AND(K$5>=$C17,K$5<=$D17),IF(K$5<$C17+COUNTIFS('SDE Plan'!$F$6:$F$78,$B17,'SDE Plan'!$B$6:$B$78,"Yes",'SDE Plan'!$L$6:$L$78,"Done"),2,1),"")) | L17: =IF($C17="","",IF(AND(L$5>=$C17,L$5<=$D17),IF(L$5<$C17+COUNTIFS('SDE Plan'!$F$6:$F$78,$B17,'SDE Plan'!$B$6:$B$78,"Yes",'SDE Plan'!$L$6:$L$78,"Done"),2,1),"")) | ... AQ17: =IF($C17="","",IF(AND(AQ$5>=$C17,AQ$5<=$D17),IF(AQ$5<$C17+COUNTIFS('SDE Plan'!$F$6:$F$78,$B17,'SDE Plan'!$B$6:$B$78,"Yes",'SDE Plan'!$L$6:$L$78,"Done"),2,1),""))
A18: SDE | B18: Applied Design & Machine Coding | C18: =IF(COUNTIFS('SDE Plan'!$F$6:$F$78,$B18,'SDE Plan'!$B$6:$B$78,"Yes")=0,"",_xlfn.MINIFS('SDE Plan'!$A$6:$A$78,'SDE Plan'!$F$6:$F$78,$B18,'SDE Plan'!$B$6:$B$78,"Yes")) -> 25 | D18: =IF(COUNTIFS('SDE Plan'!$F$6:$F$78,$B18,'SDE Plan'!$B$6:$B$78,"Yes")=0,"",_xlfn.MAXIFS('SDE Plan'!$A$6:$A$78,'SDE Plan'!$F$6:$F$78,$B18,'SDE Plan'!$B$6:$B$78,"Yes")) -> 27 | E18: =IF($C18="","",IF(AND(E$5>=$C18,E$5<=$D18),IF(E$5<$C18+COUNTIFS('SDE Plan'!$F$6:$F$78,$B18,'SDE Plan'!$B$6:$B$78,"Yes",'SDE Plan'!$L$6:$L$78,"Done"),2,1),"")) | F18: =IF($C18="","",IF(AND(F$5>=$C18,F$5<=$D18),IF(F$5<$C18+COUNTIFS('SDE Plan'!$F$6:$F$78,$B18,'SDE Plan'!$B$6:$B$78,"Yes",'SDE Plan'!$L$6:$L$78,"Done"),2,1),"")) | G18: =IF($C18="","",IF(AND(G$5>=$C18,G$5<=$D18),IF(G$5<$C18+COUNTIFS('SDE Plan'!$F$6:$F$78,$B18,'SDE Plan'!$B$6:$B$78,"Yes",'SDE Plan'!$L$6:$L$78,"Done"),2,1),"")) | H18: =IF($C18="","",IF(AND(H$5>=$C18,H$5<=$D18),IF(H$5<$C18+COUNTIFS('SDE Plan'!$F$6:$F$78,$B18,'SDE Plan'!$B$6:$B$78,"Yes",'SDE Plan'!$L$6:$L$78,"Done"),2,1),"")) | I18: =IF($C18="","",IF(AND(I$5>=$C18,I$5<=$D18),IF(I$5<$C18+COUNTIFS('SDE Plan'!$F$6:$F$78,$B18,'SDE Plan'!$B$6:$B$78,"Yes",'SDE Plan'!$L$6:$L$78,"Done"),2,1),"")) | J18: =IF($C18="","",IF(AND(J$5>=$C18,J$5<=$D18),IF(J$5<$C18+COUNTIFS('SDE Plan'!$F$6:$F$78,$B18,'SDE Plan'!$B$6:$B$78,"Yes",'SDE Plan'!$L$6:$L$78,"Done"),2,1),"")) | K18: =IF($C18="","",IF(AND(K$5>=$C18,K$5<=$D18),IF(K$5<$C18+COUNTIFS('SDE Plan'!$F$6:$F$78,$B18,'SDE Plan'!$B$6:$B$78,"Yes",'SDE Plan'!$L$6:$L$78,"Done"),2,1),"")) | L18: =IF($C18="","",IF(AND(L$5>=$C18,L$5<=$D18),IF(L$5<$C18+COUNTIFS('SDE Plan'!$F$6:$F$78,$B18,'SDE Plan'!$B$6:$B$78,"Yes",'SDE Plan'!$L$6:$L$78,"Done"),2,1),"")) | ... AQ18: =IF($C18="","",IF(AND(AQ$5>=$C18,AQ$5<=$D18),IF(AQ$5<$C18+COUNTIFS('SDE Plan'!$F$6:$F$78,$B18,'SDE Plan'!$B$6:$B$78,"Yes",'SDE Plan'!$L$6:$L$78,"Done"),2,1),""))
... A27: SDE | B27: Product Management for Engineers | C27: =IF(COUNTIFS('SDE Plan'!$F$6:$F$78,$B27,'SDE Plan'!$B$6:$B$78,"Yes")=0,"",_xlfn.MINIFS('SDE Plan'!$A$6:$A$78,'SDE Plan'!$F$6:$F$78,$B27,'SDE Plan'!$B$6:$B$78,"Yes")) | D27: =IF(COUNTIFS('SDE Plan'!$F$6:$F$78,$B27,'SDE Plan'!$B$6:$B$78,"Yes")=0,"",_xlfn.MAXIFS('SDE Plan'!$A$6:$A$78,'SDE Plan'!$F$6:$F$78,$B27,'SDE Plan'!$B$6:$B$78,"Yes")) | E27: =IF($C27="","",IF(AND(E$5>=$C27,E$5<=$D27),IF(E$5<$C27+COUNTIFS('SDE Plan'!$F$6:$F$78,$B27,'SDE Plan'!$B$6:$B$78,"Yes",'SDE Plan'!$L$6:$L$78,"Done"),2,1),"")) | F27: =IF($C27="","",IF(AND(F$5>=$C27,F$5<=$D27),IF(F$5<$C27+COUNTIFS('SDE Plan'!$F$6:$F$78,$B27,'SDE Plan'!$B$6:$B$78,"Yes",'SDE Plan'!$L$6:$L$78,"Done"),2,1),"")) | G27: =IF($C27="","",IF(AND(G$5>=$C27,G$5<=$D27),IF(G$5<$C27+COUNTIFS('SDE Plan'!$F$6:$F$78,$B27,'SDE Plan'!$B$6:$B$78,"Yes",'SDE Plan'!$L$6:$L$78,"Done"),2,1),"")) | H27: =IF($C27="","",IF(AND(H$5>=$C27,H$5<=$D27),IF(H$5<$C27+COUNTIFS('SDE Plan'!$F$6:$F$78,$B27,'SDE Plan'!$B$6:$B$78,"Yes",'SDE Plan'!$L$6:$L$78,"Done"),2,1),"")) | I27: =IF($C27="","",IF(AND(I$5>=$C27,I$5<=$D27),IF(I$5<$C27+COUNTIFS('SDE Plan'!$F$6:$F$78,$B27,'SDE Plan'!$B$6:$B$78,"Yes",'SDE Plan'!$L$6:$L$78,"Done"),2,1),"")) | J27: =IF($C27="","",IF(AND(J$5>=$C27,J$5<=$D27),IF(J$5<$C27+COUNTIFS('SDE Plan'!$F$6:$F$78,$B27,'SDE Plan'!$B$6:$B$78,"Yes",'SDE Plan'!$L$6:$L$78,"Done"),2,1),"")) | K27: =IF($C27="","",IF(AND(K$5>=$C27,K$5<=$D27),IF(K$5<$C27+COUNTIFS('SDE Plan'!$F$6:$F$78,$B27,'SDE Plan'!$B$6:$B$78,"Yes",'SDE Plan'!$L$6:$L$78,"Done"),2,1),"")) | L27: =IF($C27="","",IF(AND(L$5>=$C27,L$5<=$D27),IF(L$5<$C27+COUNTIFS('SDE Plan'!$F$6:$F$78,$B27,'SDE Plan'!$B$6:$B$78,"Yes",'SDE Plan'!$L$6:$L$78,"Done"),2,1),"")) | ... AQ27: =IF($C27="","",IF(AND(AQ$5>=$C27,AQ$5<=$D27),IF(AQ$5<$C27+COUNTIFS('SDE Plan'!$F$6:$F$78,$B27,'SDE Plan'!$B$6:$B$78,"Yes",'SDE Plan'!$L$6:$L$78,"Done"),2,1),""))
A29: 🌐 FULL-STACK TRACK
A30: Full-Stack | B30: HTML & CSS Foundations | C30: =IF(COUNTIFS('FullStack Plan'!$F$6:$F$78,$B30,'FullStack Plan'!$B$6:$B$78,"Yes")=0,"",_xlfn.MINIFS('FullStack Plan'!$A$6:$A$78,'FullStack Plan'!$F$6:$F$78,$B30,'FullStack Plan'!$B$6:$B$78,"Yes")) -> 1 | D30: =IF(COUNTIFS('FullStack Plan'!$F$6:$F$78,$B30,'FullStack Plan'!$B$6:$B$78,"Yes")=0,"",_xlfn.MAXIFS('FullStack Plan'!$A$6:$A$78,'FullStack Plan'!$F$6:$F$78,$B30,'FullStack Plan'!$B$6:$B$78,"Yes")) -> 2 | E30: =IF($C30="","",IF(AND(E$5>=$C30,E$5<=$D30),IF(E$5<$C30+COUNTIFS('FullStack Plan'!$F$6:$F$78,$B30,'FullStack Plan'!$B$6:$B$78,"Yes",'FullStack Plan'!$L$6:$L$78,"Done"),2,1),"")) -> 1 | F30: =IF($C30="","",IF(AND(F$5>=$C30,F$5<=$D30),IF(F$5<$C30+COUNTIFS('FullStack Plan'!$F$6:$F$78,$B30,'FullStack Plan'!$B$6:$B$78,"Yes",'FullStack Plan'!$L$6:$L$78,"Done"),2,1),"")) -> 1 | G30: =IF($C30="","",IF(AND(G$5>=$C30,G$5<=$D30),IF(G$5<$C30+COUNTIFS('FullStack Plan'!$F$6:$F$78,$B30,'FullStack Plan'!$B$6:$B$78,"Yes",'FullStack Plan'!$L$6:$L$78,"Done"),2,1),"")) | H30: =IF($C30="","",IF(AND(H$5>=$C30,H$5<=$D30),IF(H$5<$C30+COUNTIFS('FullStack Plan'!$F$6:$F$78,$B30,'FullStack Plan'!$B$6:$B$78,"Yes",'FullStack Plan'!$L$6:$L$78,"Done"),2,1),"")) | I30: =IF($C30="","",IF(AND(I$5>=$C30,I$5<=$D30),IF(I$5<$C30+COUNTIFS('FullStack Plan'!$F$6:$F$78,$B30,'FullStack Plan'!$B$6:$B$78,"Yes",'FullStack Plan'!$L$6:$L$78,"Done"),2,1),"")) | J30: =IF($C30="","",IF(AND(J$5>=$C30,J$5<=$D30),IF(J$5<$C30+COUNTIFS('FullStack Plan'!$F$6:$F$78,$B30,'FullStack Plan'!$B$6:$B$78,"Yes",'FullStack Plan'!$L$6:$L$78,"Done"),2,1),"")) | K30: =IF($C30="","",IF(AND(K$5>=$C30,K$5<=$D30),IF(K$5<$C30+COUNTIFS('FullStack Plan'!$F$6:$F$78,$B30,'FullStack Plan'!$B$6:$B$78,"Yes",'FullStack Plan'!$L$6:$L$78,"Done"),2,1),"")) | L30: =IF($C30="","",IF(AND(L$5>=$C30,L$5<=$D30),IF(L$5<$C30+COUNTIFS('FullStack Plan'!$F$6:$F$78,$B30,'FullStack Plan'!$B$6:$B$78,"Yes",'FullStack Plan'!$L$6:$L$78,"Done"),2,1),"")) | ... AQ30: =IF($C30="","",IF(AND(AQ$5>=$C30,AQ$5<=$D30),IF(AQ$5<$C30+COUNTIFS('FullStack Plan'!$F$6:$F$78,$B30,'FullStack Plan'!$B$6:$B$78,"Yes",'FullStack Plan'!$L$6:$L$78,"Done"),2,1),""))
A31: Full-Stack | B31: Bootstrap (supplementary) | C31: =IF(COUNTIFS('FullStack Plan'!$F$6:$F$78,$B31,'FullStack Plan'!$B$6:$B$78,"Yes")=0,"",_xlfn.MINIFS('FullStack Plan'!$A$6:$A$78,'FullStack Plan'!$F$6:$F$78,$B31,'FullStack Plan'!$B$6:$B$78,"Yes")) | D31: =IF(COUNTIFS('FullStack Plan'!$F$6:$F$78,$B31,'FullStack Plan'!$B$6:$B$78,"Yes")=0,"",_xlfn.MAXIFS('FullStack Plan'!$A$6:$A$78,'FullStack Plan'!$F$6:$F$78,$B31,'FullStack Plan'!$B$6:$B$78,"Yes")) | E31: =IF($C31="","",IF(AND(E$5>=$C31,E$5<=$D31),IF(E$5<$C31+COUNTIFS('FullStack Plan'!$F$6:$F$78,$B31,'FullStack Plan'!$B$6:$B$78,"Yes",'FullStack Plan'!$L$6:$L$78,"Done"),2,1),"")) | F31: =IF($C31="","",IF(AND(F$5>=$C31,F$5<=$D31),IF(F$5<$C31+COUNTIFS('FullStack Plan'!$F$6:$F$78,$B31,'FullStack Plan'!$B$6:$B$78,"Yes",'FullStack Plan'!$L$6:$L$78,"Done"),2,1),"")) | G31: =IF($C31="","",IF(AND(G$5>=$C31,G$5<=$D31),IF(G$5<$C31+COUNTIFS('FullStack Plan'!$F$6:$F$78,$B31,'FullStack Plan'!$B$6:$B$78,"Yes",'FullStack Plan'!$L$6:$L$78,"Done"),2,1),"")) | H31: =IF($C31="","",IF(AND(H$5>=$C31,H$5<=$D31),IF(H$5<$C31+COUNTIFS('FullStack Plan'!$F$6:$F$78,$B31,'FullStack Plan'!$B$6:$B$78,"Yes",'FullStack Plan'!$L$6:$L$78,"Done"),2,1),"")) | I31: =IF($C31="","",IF(AND(I$5>=$C31,I$5<=$D31),IF(I$5<$C31+COUNTIFS('FullStack Plan'!$F$6:$F$78,$B31,'FullStack Plan'!$B$6:$B$78,"Yes",'FullStack Plan'!$L$6:$L$78,"Done"),2,1),"")) | J31: =IF($C31="","",IF(AND(J$5>=$C31,J$5<=$D31),IF(J$5<$C31+COUNTIFS('FullStack Plan'!$F$6:$F$78,$B31,'FullStack Plan'!$B$6:$B$78,"Yes",'FullStack Plan'!$L$6:$L$78,"Done"),2,1),"")) | K31: =IF($C31="","",IF(AND(K$5>=$C31,K$5<=$D31),IF(K$5<$C31+COUNTIFS('FullStack Plan'!$F$6:$F$78,$B31,'FullStack Plan'!$B$6:$B$78,"Yes",'FullStack Plan'!$L$6:$L$78,"Done"),2,1),"")) | L31: =IF($C31="","",IF(AND(L$5>=$C31,L$5<=$D31),IF(L$5<$C31+COUNTIFS('FullStack Plan'!$F$6:$F$78,$B31,'FullStack Plan'!$B$6:$B$78,"Yes",'FullStack Plan'!$L$6:$L$78,"Done"),2,1),"")) | ... AQ31: =IF($C31="","",IF(AND(AQ$5>=$C31,AQ$5<=$D31),IF(AQ$5<$C31+COUNTIFS('FullStack Plan'!$F$6:$F$78,$B31,'FullStack Plan'!$B$6:$B$78,"Yes",'FullStack Plan'!$L$6:$L$78,"Done"),2,1),""))
A32: Full-Stack | B32: JavaScript Runtime Systems, Browser APIs & Product Labs | C32: =IF(COUNTIFS('FullStack Plan'!$F$6:$F$78,$B32,'FullStack Plan'!$B$6:$B$78,"Yes")=0,"",_xlfn.MINIFS('FullStack Plan'!$A$6:$A$78,'FullStack Plan'!$F$6:$F$78,$B32,'FullStack Plan'!$B$6:$B$78,"Yes")) -> 3 | D32: =IF(COUNTIFS('FullStack Plan'!$F$6:$F$78,$B32,'FullStack Plan'!$B$6:$B$78,"Yes")=0,"",_xlfn.MAXIFS('FullStack Plan'!$A$6:$A$78,'FullStack Plan'!$F$6:$F$78,$B32,'FullStack Plan'!$B$6:$B$78,"Yes")) -> 8 | E32: =IF($C32="","",IF(AND(E$5>=$C32,E$5<=$D32),IF(E$5<$C32+COUNTIFS('FullStack Plan'!$F$6:$F$78,$B32,'FullStack Plan'!$B$6:$B$78,"Yes",'FullStack Plan'!$L$6:$L$78,"Done"),2,1),"")) | F32: =IF($C32="","",IF(AND(F$5>=$C32,F$5<=$D32),IF(F$5<$C32+COUNTIFS('FullStack Plan'!$F$6:$F$78,$B32,'FullStack Plan'!$B$6:$B$78,"Yes",'FullStack Plan'!$L$6:$L$78,"Done"),2,1),"")) | G32: =IF($C32="","",IF(AND(G$5>=$C32,G$5<=$D32),IF(G$5<$C32+COUNTIFS('FullStack Plan'!$F$6:$F$78,$B32,'FullStack Plan'!$B$6:$B$78,"Yes",'FullStack Plan'!$L$6:$L$78,"Done"),2,1),"")) -> 1 | H32: =IF($C32="","",IF(AND(H$5>=$C32,H$5<=$D32),IF(H$5<$C32+COUNTIFS('FullStack Plan'!$F$6:$F$78,$B32,'FullStack Plan'!$B$6:$B$78,"Yes",'FullStack Plan'!$L$6:$L$78,"Done"),2,1),"")) -> 1 | I32: =IF($C32="","",IF(AND(I$5>=$C32,I$5<=$D32),IF(I$5<$C32+COUNTIFS('FullStack Plan'!$F$6:$F$78,$B32,'FullStack Plan'!$B$6:$B$78,"Yes",'FullStack Plan'!$L$6:$L$78,"Done"),2,1),"")) -> 1 | J32: =IF($C32="","",IF(AND(J$5>=$C32,J$5<=$D32),IF(J$5<$C32+COUNTIFS('FullStack Plan'!$F$6:$F$78,$B32,'FullStack Plan'!$B$6:$B$78,"Yes",'FullStack Plan'!$L$6:$L$78,"Done"),2,1),"")) -> 1 | K32: =IF($C32="","",IF(AND(K$5>=$C32,K$5<=$D32),IF(K$5<$C32+COUNTIFS('FullStack Plan'!$F$6:$F$78,$B32,'FullStack Plan'!$B$6:$B$78,"Yes",'FullStack Plan'!$L$6:$L$78,"Done"),2,1),"")) -> 1 | L32: =IF($C32="","",IF(AND(L$5>=$C32,L$5<=$D32),IF(L$5<$C32+COUNTIFS('FullStack Plan'!$F$6:$F$78,$B32,'FullStack Plan'!$B$6:$B$78,"Yes",'FullStack Plan'!$L$6:$L$78,"Done"),2,1),"")) -> 1 | ... AQ32: =IF($C32="","",IF(AND(AQ$5>=$C32,AQ$5<=$D32),IF(AQ$5<$C32+COUNTIFS('FullStack Plan'!$F$6:$F$78,$B32,'FullStack Plan'!$B$6:$B$78,"Yes",'FullStack Plan'!$L$6:$L$78,"Done"),2,1),""))
A33: Full-Stack | B33: JavaScript Object System & Engineering Patterns | C33: =IF(COUNTIFS('FullStack Plan'!$F$6:$F$78,$B33,'FullStack Plan'!$B$6:$B$78,"Yes")=0,"",_xlfn.MINIFS('FullStack Plan'!$A$6:$A$78,'FullStack Plan'!$F$6:$F$78,$B33,'FullStack Plan'!$B$6:$B$78,"Yes")) -> 9 | D33: =IF(COUNTIFS('FullStack Plan'!$F$6:$F$78,$B33,'FullStack Plan'!$B$6:$B$78,"Yes")=0,"",_xlfn.MAXIFS('FullStack Plan'!$A$6:$A$78,'FullStack Plan'!$F$6:$F$78,$B33,'FullStack Plan'!$B$6:$B$78,"Yes")) -> 10 | E33: =IF($C33="","",IF(AND(E$5>=$C33,E$5<=$D33),IF(E$5<$C33+COUNTIFS('FullStack Plan'!$F$6:$F$78,$B33,'FullStack Plan'!$B$6:$B$78,"Yes",'FullStack Plan'!$L$6:$L$78,"Done"),2,1),"")) | F33: =IF($C33="","",IF(AND(F$5>=$C33,F$5<=$D33),IF(F$5<$C33+COUNTIFS('FullStack Plan'!$F$6:$F$78,$B33,'FullStack Plan'!$B$6:$B$78,"Yes",'FullStack Plan'!$L$6:$L$78,"Done"),2,1),"")) | G33: =IF($C33="","",IF(AND(G$5>=$C33,G$5<=$D33),IF(G$5<$C33+COUNTIFS('FullStack Plan'!$F$6:$F$78,$B33,'FullStack Plan'!$B$6:$B$78,"Yes",'FullStack Plan'!$L$6:$L$78,"Done"),2,1),"")) | H33: =IF($C33="","",IF(AND(H$5>=$C33,H$5<=$D33),IF(H$5<$C33+COUNTIFS('FullStack Plan'!$F$6:$F$78,$B33,'FullStack Plan'!$B$6:$B$78,"Yes",'FullStack Plan'!$L$6:$L$78,"Done"),2,1),"")) | I33: =IF($C33="","",IF(AND(I$5>=$C33,I$5<=$D33),IF(I$5<$C33+COUNTIFS('FullStack Plan'!$F$6:$F$78,$B33,'FullStack Plan'!$B$6:$B$78,"Yes",'FullStack Plan'!$L$6:$L$78,"Done"),2,1),"")) | J33: =IF($C33="","",IF(AND(J$5>=$C33,J$5<=$D33),IF(J$5<$C33+COUNTIFS('FullStack Plan'!$F$6:$F$78,$B33,'FullStack Plan'!$B$6:$B$78,"Yes",'FullStack Plan'!$L$6:$L$78,"Done"),2,1),"")) | K33: =IF($C33="","",IF(AND(K$5>=$C33,K$5<=$D33),IF(K$5<$C33+COUNTIFS('FullStack Plan'!$F$6:$F$78,$B33,'FullStack Plan'!$B$6:$B$78,"Yes",'FullStack Plan'!$L$6:$L$78,"Done"),2,1),"")) | L33: =IF($C33="","",IF(AND(L$5>=$C33,L$5<=$D33),IF(L$5<$C33+COUNTIFS('FullStack Plan'!$F$6:$F$78,$B33,'FullStack Plan'!$B$6:$B$78,"Yes",'FullStack Plan'!$L$6:$L$78,"Done"),2,1),"")) | ... AQ33: =IF($C33="","",IF(AND(AQ$5>=$C33,AQ$5<=$D33),IF(AQ$5<$C33+COUNTIFS('FullStack Plan'!$F$6:$F$78,$B33,'FullStack Plan'!$B$6:$B$78,"Yes",'FullStack Plan'!$L$6:$L$78,"Done"),2,1),""))
A34: Full-Stack | B34: jQuery (legacy, optional) | C34: =IF(COUNTIFS('FullStack Plan'!$F$6:$F$78,$B34,'FullStack Plan'!$B$6:$B$78,"Yes")=0,"",_xlfn.MINIFS('FullStack Plan'!$A$6:$A$78,'FullStack Plan'!$F$6:$F$78,$B34,'FullStack Plan'!$B$6:$B$78,"Yes")) | D34: =IF(COUNTIFS('FullStack Plan'!$F$6:$F$78,$B34,'FullStack Plan'!$B$6:$B$78,"Yes")=0,"",_xlfn.MAXIFS('FullStack Plan'!$A$6:$A$78,'FullStack Plan'!$F$6:$F$78,$B34,'FullStack Plan'!$B$6:$B$78,"Yes")) | E34: =IF($C34="","",IF(AND(E$5>=$C34,E$5<=$D34),IF(E$5<$C34+COUNTIFS('FullStack Plan'!$F$6:$F$78,$B34,'FullStack Plan'!$B$6:$B$78,"Yes",'FullStack Plan'!$L$6:$L$78,"Done"),2,1),"")) | F34: =IF($C34="","",IF(AND(F$5>=$C34,F$5<=$D34),IF(F$5<$C34+COUNTIFS('FullStack Plan'!$F$6:$F$78,$B34,'FullStack Plan'!$B$6:$B$78,"Yes",'FullStack Plan'!$L$6:$L$78,"Done"),2,1),"")) | G34: =IF($C34="","",IF(AND(G$5>=$C34,G$5<=$D34),IF(G$5<$C34+COUNTIFS('FullStack Plan'!$F$6:$F$78,$B34,'FullStack Plan'!$B$6:$B$78,"Yes",'FullStack Plan'!$L$6:$L$78,"Done"),2,1),"")) | H34: =IF($C34="","",IF(AND(H$5>=$C34,H$5<=$D34),IF(H$5<$C34+COUNTIFS('FullStack Plan'!$F$6:$F$78,$B34,'FullStack Plan'!$B$6:$B$78,"Yes",'FullStack Plan'!$L$6:$L$78,"Done"),2,1),"")) | I34: =IF($C34="","",IF(AND(I$5>=$C34,I$5<=$D34),IF(I$5<$C34+COUNTIFS('FullStack Plan'!$F$6:$F$78,$B34,'FullStack Plan'!$B$6:$B$78,"Yes",'FullStack Plan'!$L$6:$L$78,"Done"),2,1),"")) | J34: =IF($C34="","",IF(AND(J$5>=$C34,J$5<=$D34),IF(J$5<$C34+COUNTIFS('FullStack Plan'!$F$6:$F$78,$B34,'FullStack Plan'!$B$6:$B$78,"Yes",'FullStack Plan'!$L$6:$L$78,"Done"),2,1),"")) | K34: =IF($C34="","",IF(AND(K$5>=$C34,K$5<=$D34),IF(K$5<$C34+COUNTIFS('FullStack Plan'!$F$6:$F$78,$B34,'FullStack Plan'!$B$6:$B$78,"Yes",'FullStack Plan'!$L$6:$L$78,"Done"),2,1),"")) | L34: =IF($C34="","",IF(AND(L$5>=$C34,L$5<=$D34),IF(L$5<$C34+COUNTIFS('FullStack Plan'!$F$6:$F$78,$B34,'FullStack Plan'!$B$6:$B$78,"Yes",'FullStack Plan'!$L$6:$L$78,"Done"),2,1),"")) | ... AQ34: =IF($C34="","",IF(AND(AQ$5>=$C34,AQ$5<=$D34),IF(AQ$5<$C34+COUNTIFS('FullStack Plan'!$F$6:$F$78,$B34,'FullStack Plan'!$B$6:$B$78,"Yes",'FullStack Plan'!$L$6:$L$78,"Done"),2,1),""))
A35: Full-Stack | B35: React & Frontend Product Architecture Fundamentals | C35: =IF(COUNTIFS('FullStack Plan'!$F$6:$F$78,$B35,'FullStack Plan'!$B$6:$B$78,"Yes")=0,"",_xlfn.MINIFS('FullStack Plan'!$A$6:$A$78,'FullStack Plan'!$F$6:$F$78,$B35,'FullStack Plan'!$B$6:$B$78,"Yes")) -> 11 | D35: =IF(COUNTIFS('FullStack Plan'!$F$6:$F$78,$B35,'FullStack Plan'!$B$6:$B$78,"Yes")=0,"",_xlfn.MAXIFS('FullStack Plan'!$A$6:$A$78,'FullStack Plan'!$F$6:$F$78,$B35,'FullStack Plan'!$B$6:$B$78,"Yes")) -> 14 | E35: =IF($C35="","",IF(AND(E$5>=$C35,E$5<=$D35),IF(E$5<$C35+COUNTIFS('FullStack Plan'!$F$6:$F$78,$B35,'FullStack Plan'!$B$6:$B$78,"Yes",'FullStack Plan'!$L$6:$L$78,"Done"),2,1),"")) | F35: =IF($C35="","",IF(AND(F$5>=$C35,F$5<=$D35),IF(F$5<$C35+COUNTIFS('FullStack Plan'!$F$6:$F$78,$B35,'FullStack Plan'!$B$6:$B$78,"Yes",'FullStack Plan'!$L$6:$L$78,"Done"),2,1),"")) | G35: =IF($C35="","",IF(AND(G$5>=$C35,G$5<=$D35),IF(G$5<$C35+COUNTIFS('FullStack Plan'!$F$6:$F$78,$B35,'FullStack Plan'!$B$6:$B$78,"Yes",'FullStack Plan'!$L$6:$L$78,"Done"),2,1),"")) | H35: =IF($C35="","",IF(AND(H$5>=$C35,H$5<=$D35),IF(H$5<$C35+COUNTIFS('FullStack Plan'!$F$6:$F$78,$B35,'FullStack Plan'!$B$6:$B$78,"Yes",'FullStack Plan'!$L$6:$L$78,"Done"),2,1),"")) | I35: =IF($C35="","",IF(AND(I$5>=$C35,I$5<=$D35),IF(I$5<$C35+COUNTIFS('FullStack Plan'!$F$6:$F$78,$B35,'FullStack Plan'!$B$6:$B$78,"Yes",'FullStack Plan'!$L$6:$L$78,"Done"),2,1),"")) | J35: =IF($C35="","",IF(AND(J$5>=$C35,J$5<=$D35),IF(J$5<$C35+COUNTIFS('FullStack Plan'!$F$6:$F$78,$B35,'FullStack Plan'!$B$6:$B$78,"Yes",'FullStack Plan'!$L$6:$L$78,"Done"),2,1),"")) | K35: =IF($C35="","",IF(AND(K$5>=$C35,K$5<=$D35),IF(K$5<$C35+COUNTIFS('FullStack Plan'!$F$6:$F$78,$B35,'FullStack Plan'!$B$6:$B$78,"Yes",'FullStack Plan'!$L$6:$L$78,"Done"),2,1),"")) | L35: =IF($C35="","",IF(AND(L$5>=$C35,L$5<=$D35),IF(L$5<$C35+COUNTIFS('FullStack Plan'!$F$6:$F$78,$B35,'FullStack Plan'!$B$6:$B$78,"Yes",'FullStack Plan'!$L$6:$L$78,"Done"),2,1),"")) | ... AQ35: =IF($C35="","",IF(AND(AQ$5>=$C35,AQ$5<=$D35),IF(AQ$5<$C35+COUNTIFS('FullStack Plan'!$F$6:$F$78,$B35,'FullStack Plan'!$B$6:$B$78,"Yes",'FullStack Plan'!$L$6:$L$78,"Done"),2,1),""))
A36: Full-Stack | B36: Backend Product Systems, APIs & Production Engineering (MERN) | C36: =IF(COUNTIFS('FullStack Plan'!$F$6:$F$78,$B36,'FullStack Plan'!$B$6:$B$78,"Yes")=0,"",_xlfn.MINIFS('FullStack Plan'!$A$6:$A$78,'FullStack Plan'!$F$6:$F$78,$B36,'FullStack Plan'!$B$6:$B$78,"Yes")) -> 15 | D36: =IF(COUNTIFS('FullStack Plan'!$F$6:$F$78,$B36,'FullStack Plan'!$B$6:$B$78,"Yes")=0,"",_xlfn.MAXIFS('FullStack Plan'!$A$6:$A$78,'FullStack Plan'!$F$6:$F$78,$B36,'FullStack Plan'!$B$6:$B$78,"Yes")) -> 18 | E36: =IF($C36="","",IF(AND(E$5>=$C36,E$5<=$D36),IF(E$5<$C36+COUNTIFS('FullStack Plan'!$F$6:$F$78,$B36,'FullStack Plan'!$B$6:$B$78,"Yes",'FullStack Plan'!$L$6:$L$78,"Done"),2,1),"")) | F36: =IF($C36="","",IF(AND(F$5>=$C36,F$5<=$D36),IF(F$5<$C36+COUNTIFS('FullStack Plan'!$F$6:$F$78,$B36,'FullStack Plan'!$B$6:$B$78,"Yes",'FullStack Plan'!$L$6:$L$78,"Done"),2,1),"")) | G36: =IF($C36="","",IF(AND(G$5>=$C36,G$5<=$D36),IF(G$5<$C36+COUNTIFS('FullStack Plan'!$F$6:$F$78,$B36,'FullStack Plan'!$B$6:$B$78,"Yes",'FullStack Plan'!$L$6:$L$78,"Done"),2,1),"")) | H36: =IF($C36="","",IF(AND(H$5>=$C36,H$5<=$D36),IF(H$5<$C36+COUNTIFS('FullStack Plan'!$F$6:$F$78,$B36,'FullStack Plan'!$B$6:$B$78,"Yes",'FullStack Plan'!$L$6:$L$78,"Done"),2,1),"")) | I36: =IF($C36="","",IF(AND(I$5>=$C36,I$5<=$D36),IF(I$5<$C36+COUNTIFS('FullStack Plan'!$F$6:$F$78,$B36,'FullStack Plan'!$B$6:$B$78,"Yes",'FullStack Plan'!$L$6:$L$78,"Done"),2,1),"")) | J36: =IF($C36="","",IF(AND(J$5>=$C36,J$5<=$D36),IF(J$5<$C36+COUNTIFS('FullStack Plan'!$F$6:$F$78,$B36,'FullStack Plan'!$B$6:$B$78,"Yes",'FullStack Plan'!$L$6:$L$78,"Done"),2,1),"")) | K36: =IF($C36="","",IF(AND(K$5>=$C36,K$5<=$D36),IF(K$5<$C36+COUNTIFS('FullStack Plan'!$F$6:$F$78,$B36,'FullStack Plan'!$B$6:$B$78,"Yes",'FullStack Plan'!$L$6:$L$78,"Done"),2,1),"")) | L36: =IF($C36="","",IF(AND(L$5>=$C36,L$5<=$D36),IF(L$5<$C36+COUNTIFS('FullStack Plan'!$F$6:$F$78,$B36,'FullStack Plan'!$B$6:$B$78,"Yes",'FullStack Plan'!$L$6:$L$78,"Done"),2,1),"")) | ... AQ36: =IF($C36="","",IF(AND(AQ$5>=$C36,AQ$5<=$D36),IF(AQ$5<$C36+COUNTIFS('FullStack Plan'!$F$6:$F$78,$B36,'FullStack Plan'!$B$6:$B$78,"Yes",'FullStack Plan'!$L$6:$L$78,"Done"),2,1),""))
